Workbook

Sheet راهنما
A1: دفتر حسابداری ساختمان «دنگ» — نمونه اولیه (Prototype)
A3: این کارپوشه نمونه اولیه قواعد مالی برنامه اندرویدی «دنگ» است و تمام داده‌های آن ساختگی (نمونه) هستند.
A4: موتور محاسبه اصلی در برنامه (کاتلین) پیاده‌سازی و آزمون شده است؛ این فایل برای اعتبارسنجی قواعد است.
A6: راهنمای رنگ‌ها:
A7: • سلول زرد با متن آبی = ورودی قابل ویرایش
A8: • سلول سفید با متن سیاه = محاسبه با فرمول (ویرایش نکنید)
A9: • متن سبز = پیوند به برگه دیگر
A10: • برگه «کنترل‌ها» باید همه موارد را «درست» نشان دهد.
A12: قواعد کلیدی:
A13: • مبالغ به کوچک‌ترین واحد پول (ریال) و به صورت عدد صحیح ثبت می‌شوند.
A14: • سهم هر واحد = مبلغ × وزن واحد ÷ مجموع وزن‌ها؛ سپس به مضرب «واحد گرد کردن» کاهش می‌یابد.
A15: • باقیمانده گرد کردن به روش «بزرگ‌ترین باقیمانده» توزیع می‌شود (تساوی: ترتیب واحد)؛ هیچ باقیمانده‌ای حذف نمی‌شود.
... A24: برنامه اصلی تاریخچه سکونت، چند دوره، تعرفه پلکانی آب و اصلاحیه پس از قطعی شدن را پشتیبانی می‌کند.
A26: نمونه سلول ورودی | B26: =1+1

Sheet تنظیمات
A1: تنظیمات ساختمان و دوره
A3: عنوان | B3: مقدار
A4: نام ساختمان | B4: ساختمان نمونه ۹ واحدی
A5: نشانی | B5: نشانی نمونه — ساختگی
A6: واحد پول | B6: ریال
A7: واحد گرد کردن سهم‌ها (ریال) | B7: 1000
A8: نام دوره | B8: مهر ۱۴۰۵ (نمونه)
A9: شروع دوره (شمسی) | B9: 1405/07/01
A10: پایان دوره (شمسی) | B10: 1405/07/30
A11: تقویم | B11: هجری شمسی
A12: مبنای تسهیم سهم مشترک آب | B12: مساوی

Sheet واحدها
A1: واحدها و ساکنان
A2: تعداد ساکنان «نمونه» است و باید توسط مدیر ساختمان اصلاح شود.
A4: شناسه واحد | B4: طبقه | C4: شماره واحد | D4: متراژ (m²) | E4: تعداد ساکنان (نمونه) | F4: فعال | G4: یادداشت | H4: ترتیب | I4: مصرف آب دوره (m³) | J4: مصرف (لیتر) | K4: پارکینگ تخصیصی | L4: پارکینگ در استفاده
A5: 1-1 | B5: 1 | C5: 1 | D5: 60 | E5: 2 | F5: بله | H5: =ROW()-4 | I5: =SUMIFS('کنتورها'!$I$5:$I$30,'کنتورها'!$C$5:$C$30,A5,'کنتورها'!$B$5:$B$30,"واحد") | J5: =ROUND(I5*1000,0) | K5: =COUNTIFS('پارکینگ'!$B$5:$B$30,A5) | L5: =COUNTIFS('پارکینگ'!$B$5:$B$30,A5,'پارکینگ'!$D$5:$D$30,"بله")
A6: 1-2 | B6: 1 | C6: 2 | D6: 60 | E6: 1 | F6: بله | H6: =ROW()-4 | I6: =SUMIFS('کنتورها'!$I$5:$I$30,'کنتورها'!$C$5:$C$30,A6,'کنتورها'!$B$5:$B$30,"واحد") | J6: =ROUND(I6*1000,0) | K6: =COUNTIFS('پارکینگ'!$B$5:$B$30,A6) | L6: =COUNTIFS('پارکینگ'!$B$5:$B$30,A6,'پارکینگ'!$D$5:$D$30,"بله")
A7: 1-3 | B7: 1 | C7: 3 | D7: 70 | E7: 3 | F7: بله | H7: =ROW()-4 | I7: =SUMIFS('کنتورها'!$I$5:$I$30,'کنتورها'!$C$5:$C$30,A7,'کنتورها'!$B$5:$B$30,"واحد") | J7: =ROUND(I7*1000,0) | K7: =COUNTIFS('پارکینگ'!$B$5:$B$30,A7) | L7: =COUNTIFS('پارکینگ'!$B$5:$B$30,A7,'پارکینگ'!$D$5:$D$30,"بله")
A8: 2-1 | B8: 2 | C8: 1 | D8: 156 | E8: 4 | F8: بله | H8: =ROW()-4 | I8: =SUMIFS('کنتورها'!$I$5:$I$30,'کنتورها'!$C$5:$C$30,A8,'کنتورها'!$B$5:$B$30,"واحد") | J8: =ROUND(I8*1000,0) | K8: =COUNTIFS('پارکینگ'!$B$5:$B$30,A8) | L8: =COUNTIFS('پارکینگ'!$B$5:$B$30,A8,'پارکینگ'!$D$5:$D$30,"بله")
A9: 2-2 | B9: 2 | C9: 2 | D9: 100 | E9: 2 | F9: بله | H9: =ROW()-4 | I9: =SUMIFS('کنتورها'!$I$5:$I$30,'کنتورها'!$C$5:$C$30,A9,'کنتورها'!$B$5:$B$30,"واحد") | J9: =ROUND(I9*1000,0) | K9: =COUNTIFS('پارکینگ'!$B$5:$B$30,A9) | L9: =COUNTIFS('پارکینگ'!$B$5:$B$30,A9,'پارکینگ'!$D$5:$D$30,"بله")
A10: 3-1 | B10: 3 | C10: 1 | D10: 156 | E10: 5 | F10: بله | H10: =ROW()-4 | I10: =SUMIFS('کنتورها'!$I$5:$I$30,'کنتورها'!$C$5:$C$30,A10,'کنتورها'!$B$5:$B$30,"واحد") | J10: =ROUND(I10*1000,0) | K10: =COUNTIFS('پارکینگ'!$B$5:$B$30,A10) | L10: =COUNTIFS('پارکینگ'!$B$5:$B$30,A10,'پارکینگ'!$D$5:$D$30,"بله")
A11: 3-2 | B11: 3 | C11: 2 | D11: 100 | E11: 3 | F11: بله | H11: =ROW()-4 | I11: =SUMIFS('کنتورها'!$I$5:$I$30,'کنتورها'!$C$5:$C$30,A11,'کنتورها'!$B$5:$B$30,"واحد") | J11: =ROUND(I11*1000,0) | K11: =COUNTIFS('پارکینگ'!$B$5:$B$30,A11) | L11: =COUNTIFS('پارکینگ'!$B$5:$B$30,A11,'پارکینگ'!$D$5:$D$30,"بله")
A12: 4-1 | B12: 4 | C12: 1 | D12: 156 | E12: 4 | F12: بله | H12: =ROW()-4 | I12: =SUMIFS('کنتورها'!$I$5:$I$30,'کنتورها'!$C$5:$C$30,A12,'کنتورها'!$B$5:$B$30,"واحد") | J12: =ROUND(I12*1000,0) | K12: =COUNTIFS('پارکینگ'!$B$5:$B$30,A12) | L12: =COUNTIFS('پارکینگ'!$B$5:$B$30,A12,'پارکینگ'!$D$5:$D$30,"بله")
A13: 4-2 | B13: 4 | C13: 2 | D13: 100 | E13: 2 | F13: بله | H13: =ROW()-4 | I13: =SUMIFS('کنتورها'!$I$5:$I$30,'کنتورها'!$C$5:$C$30,A13,'کنتورها'!$B$5:$B$30,"واحد") | J13: =ROUND(I13*1000,0) | K13: =COUNTIFS('پارکینگ'!$B$5:$B$30,A13) | L13: =COUNTIFS('پارکینگ'!$B$5:$B$30,A13,'پارکینگ'!$D$5:$D$30,"بله")
A14: جمع | D14: =SUM(D5:D13) | E14: =SUM(E5:E13) | I14: =SUM(I5:I13) | J14: =SUM(J5:J13) | K14: =SUM(K5:K13) | L14: =SUM(L5:L13)

Sheet پارکینگ
A1: فهرست و تخصیص پارکینگ
A2: تخصیص‌ها ساختگی‌اند. مالکیت/تخصیص از «استفاده واقعی» جداست؛ مسئولیت هزینه با سیاست هر هزینه تعیین می‌شود.
A4: شناسه جای پارک | B4: واحد | C4: نوع رابطه | D4: در استفاده | E4: خودرو / یادداشت
A5: P1 | B5: 2-1 | C5: مالکیت | D5: بله | E5: خودرو نمونه A
A6: P2 | B6: 2-1 | C6: مالکیت | D6: خیر
A7: P3 | B7: 3-1 | C7: مالکیت | D7: بله | E7: خودرو نمونه B
A8: P4 | B8: 3-1 | C8: مالکیت | D8: بله | E8: خودرو نمونه C
A9: P5 | B9: 4-1 | C9: مالکیت | D9: بله | E9: خودرو نمونه D
A10: P6 | B10: 2-2 | C10: تخصیص | D10: بله | E10: خودرو نمونه E
A11: P7 | B11: 3-2 | C11: اجاره | D11: بله | E11: خودرو نمونه F
A12: P8 | D12: خیر | E12: بدون تخصیص

Sheet کنتورها
A1: قرائت کنتورهای آب (m³)
A2: قرائت‌ها ساختگی‌اند. مصرف منفی بدون علامت گردش کنتور «خطا» است و در کنترل‌ها گزارش می‌شود.
A4: شناسه کنتور | B4: نقش | C4: واحد | D4: قرائت قبلی | E4: قرائت فعلی | F4: گردش کنتور؟ | G4: حد گردش (m³) | H4: یادداشت / تعویض | I4: مصرف (m³) | J4: وضعیت | L4: تطبیق کنتور اصلی
A5: M-MAIN | B5: اصلی | D5: 5120 | E5: 5262 | F5: خیر | H5: کنتور اصلی ساختمان | I5: =IF(OR(D5="",E5=""),0,IF(E5>=D5,E5-D5,IF(AND(F5="بله",G5>0),G5-D5+E5,0))) | J5: =IF(A5="","",IF(OR(D5="",E5=""),"قرائت ناقص",IF(E5>=D5,"عادی",IF(AND(F5="بله",G5>0),"گردش کنتور","خطا: مصرف منفی")))) | L5: مصرف کنتور اصلی (m³) | M5: =SUMIFS(I5:I30,B5:B30,"اصلی")
A6: M-11 | B6: واحد | C6: 1-1 | D6: 310.2 | E6: 322.7 | F6: خیر | I6: =IF(OR(D6="",E6=""),0,IF(E6>=D6,E6-D6,IF(AND(F6="بله",G6>0),G6-D6+E6,0))) | J6: =IF(A6="","",IF(OR(D6="",E6=""),"قرائت ناقص",IF(E6>=D6,"عادی",IF(AND(F6="بله",G6>0),"گردش کنتور","خطا: مصرف منفی")))) | L6: مجموع مصرف کنتورهای واحد (m³) | M6: =SUMIFS(I5:I30,B5:B30,"واحد")
A7: M-12 | B7: واحد | C7: 1-2 | D7: 205 | E7: 205 | F7: خیر | H7: مصرف صفر (نمونه) | I7: =IF(OR(D7="",E7=""),0,IF(E7>=D7,E7-D7,IF(AND(F7="بله",G7>0),G7-D7+E7,0))) | J7: =IF(A7="","",IF(OR(D7="",E7=""),"قرائت ناقص",IF(E7>=D7,"عادی",IF(AND(F7="بله",G7>0),"گردش کنتور","خطا: مصرف منفی")))) | L7: مصرف تخصیص‌نیافته (m³) | M7: =M5-M6
A8: M-13 | B8: واحد | C8: 1-3 | D8: 9998.5 | E8: 3.2 | F8: بله | G8: 10000 | H8: گردش کنتور از ۹۹۹۹ به صفر | I8: =IF(OR(D8="",E8=""),0,IF(E8>=D8,E8-D8,IF(AND(F8="بله",G8>0),G8-D8+E8,0))) | J8: =IF(A8="","",IF(OR(D8="",E8=""),"قرائت ناقص",IF(E8>=D8,"عادی",IF(AND(F8="بله",G8>0),"گردش کنتور","خطا: مصرف منفی")))) | L8: درصد تخصیص‌نیافته | M8: =IF(M5=0,0,M7/M5)
A9: M-21 | B9: واحد | C9: 2-1 | D9: 1402.3 | E9: 1421.1 | F9: خیر | I9: =IF(OR(D9="",E9=""),0,IF(E9>=D9,E9-D9,IF(AND(F9="بله",G9>0),G9-D9+E9,0))) | J9: =IF(A9="","",IF(OR(D9="",E9=""),"قرائت ناقص",IF(E9>=D9,"عادی",IF(AND(F9="بله",G9>0),"گردش کنتور","خطا: مصرف منفی")))) | L9: تعداد خطای قرائت | M9: =COUNTIF(J5:J30,"خطا*")
A10: M-22-OLD | B10: واحد | C10: 2-2 | D10: 812 | E10: 815.4 | F10: خیر | H10: کنتور قدیم - قرائت نهایی هنگام تعویض | I10: =IF(OR(D10="",E10=""),0,IF(E10>=D10,E10-D10,IF(AND(F10="بله",G10>0),G10-D10+E10,0))) | J10: =IF(A10="","",IF(OR(D10="",E10=""),"قرائت ناقص",IF(E10>=D10,"عادی",IF(AND(F10="بله",G10>0),"گردش کنتور","خطا: مصرف منفی")))) | L10: تعداد قرائت ناقص | M10: =COUNTIF(J5:J30,"قرائت ناقص")
A11: M-22-NEW | B11: واحد | C11: 2-2 | D11: 0 | E11: 6.1 | F11: خیر | H11: کنتور جدید - قرائت اولیه صفر | I11: =IF(OR(D11="",E11=""),0,IF(E11>=D11,E11-D11,IF(AND(F11="بله",G11>0),G11-D11+E11,0))) | J11: =IF(A11="","",IF(OR(D11="",E11=""),"قرائت ناقص",IF(E11>=D11,"عادی",IF(AND(F11="بله",G11>0),"گردش کنتور","خطا: مصرف منفی"))))
A12: M-31 | B12: واحد | C12: 3-1 | D12: 1650 | E12: 1672.4 | F12: خیر | I12: =IF(OR(D12="",E12=""),0,IF(E12>=D12,E12-D12,IF(AND(F12="بله",G12>0),G12-D12+E12,0))) | J12: =IF(A12="","",IF(OR(D12="",E12=""),"قرائت ناقص",IF(E12>=D12,"عادی",IF(AND(F12="بله",G12>0),"گردش کنتور","خطا: مصرف منفی"))))
A13: M-32 | B13: واحد | C13: 3-2 | D13: 980.5 | E13: 994.2 | F13: خیر | I13: =IF(OR(D13="",E13=""),0,IF(E13>=D13,E13-D13,IF(AND(F13="بله",G13>0),G13-D13+E13,0))) | J13: =IF(A13="","",IF(OR(D13="",E13=""),"قرائت ناقص",IF(E13>=D13,"عادی",IF(AND(F13="بله",G13>0),"گردش کنتور","خطا: مصرف منفی"))))
A14: M-41 | B14: واحد | C14: 4-1 | D14: 1710 | E14: 1731.3 | F14: خیر | I14: =IF(OR(D14="",E14=""),0,IF(E14>=D14,E14-D14,IF(AND(F14="بله",G14>0),G14-D14+E14,0))) | J14: =IF(A14="","",IF(OR(D14="",E14=""),"قرائت ناقص",IF(E14>=D14,"عادی",IF(AND(F14="بله",G14>0),"گردش کنتور","خطا: مصرف منفی"))))
A15: M-42 | B15: واحد | C15: 4-2 | D15: 1005 | E15: 1017.6 | F15: خیر | I15: =IF(OR(D15="",E15=""),0,IF(E15>=D15,E15-D15,IF(AND(F15="بله",G15>0),G15-D15+E15,0))) | J15: =IF(A15="","",IF(OR(D15="",E15=""),"قرائت ناقص",IF(E15>=D15,"عادی",IF(AND(F15="بله",G15>0),"گردش کنتور","خطا: مصرف منفی"))))
I16: =IF(OR(D16="",E16=""),0,IF(E16>=D16,E16-D16,IF(AND(F16="بله",G16>0),G16-D16+E16,0))) | J16: =IF(A16="","",IF(OR(D16="",E16=""),"قرائت ناقص",IF(E16>=D16,"عادی",IF(AND(F16="بله",G16>0),"گردش کنتور","خطا: مصرف منفی"))))
I17: =IF(OR(D17="",E17=""),0,IF(E17>=D17,E17-D17,IF(AND(F17="بله",G17>0),G17-D17+E17,0))) | J17: =IF(A17="","",IF(OR(D17="",E17=""),"قرائت ناقص",IF(E17>=D17,"عادی",IF(AND(F17="بله",G17>0),"گردش کنتور","خطا: مصرف منفی"))))
I18: =IF(OR(D18="",E18=""),0,IF(E18>=D18,E18-D18,IF(AND(F18="بله",G18>0),G18-D18+E18,0))) | J18: =IF(A18="","",IF(OR(D18="",E18=""),"قرائت ناقص",IF(E18>=D18,"عادی",IF(AND(F18="بله",G18>0),"گردش کنتور","خطا: مصرف منفی"))))
I19: =IF(OR(D19="",E19=""),0,IF(E19>=D19,E19-D19,IF(AND(F19="بله",G19>0),G19-D19+E19,0))) | J19: =IF(A19="","",IF(OR(D19="",E19=""),"قرائت ناقص",IF(E19>=D19,"عادی",IF(AND(F19="بله",G19>0),"گردش کنتور","خطا: مصرف منفی"))))
I20: =IF(OR(D20="",E20=""),0,IF(E20>=D20,E20-D20,IF(AND(F20="بله",G20>0),G20-D20+E20,0))) | J20: =IF(A20="","",IF(OR(D20="",E20=""),"قرائت ناقص",IF(E20>=D20,"عادی",IF(AND(F20="بله",G20>0),"گردش کنتور","خطا: مصرف منفی"))))
I21: =IF(OR(D21="",E21=""),0,IF(E21>=D21,E21-D21,IF(AND(F21="بله",G21>0),G21-D21+E21,0))) | J21: =IF(A21="","",IF(OR(D21="",E21=""),"قرائت ناقص",IF(E21>=D21,"عادی",IF(AND(F21="بله",G21>0),"گردش کنتور","خطا: مصرف منفی"))))
I22: =IF(OR(D22="",E22=""),0,IF(E22>=D22,E22-D22,IF(AND(F22="بله",G22>0),G22-D22+E22,0))) | J22: =IF(A22="","",IF(OR(D22="",E22=""),"قرائت ناقص",IF(E22>=D22,"عادی",IF(AND(F22="بله",G22>0),"گردش کنتور","خطا: مصرف منفی"))))
I23: =IF(OR(D23="",E23=""),0,IF(E23>=D23,E23-D23,IF(AND(F23="بله",G23>0),G23-D23+E23,0))) | J23: =IF(A23="","",IF(OR(D23="",E23=""),"قرائت ناقص",IF(E23>=D23,"عادی",IF(AND(F23="بله",G23>0),"گردش کنتور","خطا: مصرف منفی"))))
I24: =IF(OR(D24="",E24=""),0,IF(E24>=D24,E24-D24,IF(AND(F24="بله",G24>0),G24-D24+E24,0))) | J24: =IF(A24="","",IF(OR(D24="",E24=""),"قرائت ناقص",IF(E24>=D24,"عادی",IF(AND(F24="بله",G24>0),"گردش کنتور","خطا: مصرف منفی"))))
I25: =IF(OR(D25="",E25=""),0,IF(E25>=D25,E25-D25,IF(AND(F25="بله",G25>0),G25-D25+E25,0))) | J25: =IF(A25="","",IF(OR(D25="",E25=""),"قرائت ناقص",IF(E25>=D25,"عادی",IF(AND(F25="بله",G25>0),"گردش کنتور","خطا: مصرف منفی"))))
I26: =IF(OR(D26="",E26=""),0,IF(E26>=D26,E26-D26,IF(AND(F26="بله",G26>0),G26-D26+E26,0))) | J26: =IF(A26="","",IF(OR(D26="",E26=""),"قرائت ناقص",IF(E26>=D26,"عادی",IF(AND(F26="بله",G26>0),"گردش کنتور","خطا: مصرف منفی"))))
I27: =IF(OR(D27="",E27=""),0,IF(E27>=D27,E27-D27,IF(AND(F27="بله",G27>0),G27-D27+E27,0))) | J27: =IF(A27="","",IF(OR(D27="",E27=""),"قرائت ناقص",IF(E27>=D27,"عادی",IF(AND(F27="بله",G27>0),"گردش کنتور","خطا: مصرف منفی"))))
... I30: =IF(OR(D30="",E30=""),0,IF(E30>=D30,E30-D30,IF(AND(F30="بله",G30>0),G30-D30+E30,0))) | J30: =IF(A30="","",IF(OR(D30="",E30=""),"قرائت ناقص",IF(E30>=D30,"عادی",IF(AND(F30="بله",G30>0),"گردش کنتور","خطا: مصرف منفی"))))

Sheet دوره‌ها
A1: دوره‌های صورتحساب
A4: شناسه دوره | B4: نام | C4: شروع | D4: پایان | E4: مهلت پرداخت | F4: وضعیت
A5: 1405-07 | B5: مهر ۱۴۰۵ (نمونه) | C5: 1405/07/01 | D5: 1405/07/30 | E5: 1405/08/10 | F5: پیش‌نویس
A7: وضعیت «قطعی» یعنی ورودی‌ها، قواعد و نتایج دوره ثابت می‌شوند و اصلاح فقط با سند تعدیل مرتبط انجام می‌شود.

Sheet دسته‌ها
A1: دسته‌های هزینه و سیاست پیش‌فرض تسهیم
A2: نمونه‌اند، نه قاعده حقوقی. هر ساختمان سیاست خود را انتخاب می‌کند.
A4: دسته | B4: مبنای پیش‌فرض | C4: صندوق پیش‌فرض | D4: مربوط به آب؟ | E4: فعال
A5: نظافت | B5: نفر | C5: عملیاتی | D5: خیر | E5: بله
A6: هزینه‌های عمومی | B6: مساوی | C6: عملیاتی | D6: خیر | E6: بله
A7: تعمیر و نگهداری ساختمان | B7: متراژ | C7: عملیاتی | D7: خیر | E7: بله
A8: آب | B8: مصرف + سهم مشترک | C8: عملیاتی | D8: بله | E8: بله
A9: برق پارکینگ | B9: پارکینگ (در استفاده) | C9: عملیاتی | D9: خیر | E9: بله
A10: سرویس آسانسور | B10: وزنی | C10: عملیاتی | D10: خیر | E10: بله
A11: تعمیرات اختصاصی | B11: مبلغ صریح | C11: عملیاتی | D11: خیر | E11: بله
A12: تعمیرات اضطراری | B12: بدون تسهیم (صندوق) | C12: اندوخته | D12: خیر | E12: بله
A13: اندوخته | B13: مساوی | C13: اندوخته | D13: خیر | E13: بله
A14: برق مشاعات | B14: متراژ | C14: عملیاتی | D14: خیر | E14: بله
A15: لوله‌کشی | B15: مساوی | C15: عملیاتی | D15: خیر | E15: بله
... A19: سایر | B19: مساوی | C19: عملیاتی | D19: خیر | E19: بله

Sheet هزینه‌ها
A1: ثبت هزینه‌ها (تعهد) — پرداخت به تامین‌کننده جداگانه ثبت می‌شود
A4: شناسه | B4: تاریخ | C4: شرح | D4: دسته | E4: تامین‌کننده | F4: مبلغ (ریال) | G4: مبنای تسهیم | H4: صندوق | I4: دوره | J4: پرداخت‌شده | K4: مانده بدهی | L4: وضعیت پرداخت | M4: مرجع سند | N4: یادداشت
A5: E1 | B5: 1405/07/05 | C5: نظافت راه‌پله - مهر | D5: نظافت | E5: شرکت خدماتی نمونه | F5: 9000000 | G5: نفر | H5: عملیاتی | I5: 1405-07 | J5: =SUMIFS('پرداخت‌ها'!$C$5:$C$34,'پرداخت‌ها'!$B$5:$B$34,A5) | K5: =N(F5)-J5 | L5: =IF(N(F5)=0,"",IF(J5=0,"پرداخت‌نشده",IF(J5<F5,"پرداخت جزئی",IF(J5=F5,"پرداخت‌شده","پرداخت مازاد!"))))
A6: E2 | B6: 1405/07/05 | C6: هزینه‌های عمومی ماهانه | D6: هزینه‌های عمومی | F6: 4500000 | G6: مساوی | H6: عملیاتی | I6: 1405-07 | J6: =SUMIFS('پرداخت‌ها'!$C$5:$C$34,'پرداخت‌ها'!$B$5:$B$34,A6) | K6: =N(F6)-J6 | L6: =IF(N(F6)=0,"",IF(J6=0,"پرداخت‌نشده",IF(J6<F6,"پرداخت جزئی",IF(J6=F6,"پرداخت‌شده","پرداخت مازاد!"))))
A7: E3 | B7: 1405/07/12 | C7: سرویس موتورخانه و نگهداری | D7: تعمیر و نگهداری ساختمان | E7: تاسیسات نمونه | F7: 12000000 | G7: متراژ | H7: عملیاتی | I7: 1405-07 | J7: =SUMIFS('پرداخت‌ها'!$C$5:$C$34,'پرداخت‌ها'!$B$5:$B$34,A7) | K7: =N(F7)-J7 | L7: =IF(N(F7)=0,"",IF(J7=0,"پرداخت‌نشده",IF(J7<F7,"پرداخت جزئی",IF(J7=F7,"پرداخت‌شده","پرداخت مازاد!"))))
A8: E4 | B8: 1405/07/28 | C8: قبض آب دوره | D8: آب | E8: شرکت آب (نمونه) | F8: 18000000 | G8: مصرف + سهم مشترک | H8: عملیاتی | I8: 1405-07 | J8: =SUMIFS('پرداخت‌ها'!$C$5:$C$34,'پرداخت‌ها'!$B$5:$B$34,A8) | K8: =N(F8)-J8 | L8: =IF(N(F8)=0,"",IF(J8=0,"پرداخت‌نشده",IF(J8<F8,"پرداخت جزئی",IF(J8=F8,"پرداخت‌شده","پرداخت مازاد!"))))
A9: E5 | B9: 1405/07/28 | C9: قبض برق پارکینگ | D9: برق پارکینگ | E9: شرکت برق (نمونه) | F9: 1600000 | G9: پارکینگ (در استفاده) | H9: عملیاتی | I9: 1405-07 | J9: =SUMIFS('پرداخت‌ها'!$C$5:$C$34,'پرداخت‌ها'!$B$5:$B$34,A9) | K9: =N(F9)-J9 | L9: =IF(N(F9)=0,"",IF(J9=0,"پرداخت‌نشده",IF(J9<F9,"پرداخت جزئی",IF(J9=F9,"پرداخت‌شده","پرداخت مازاد!"))))
A10: E6 | B10: 1405/07/15 | C10: سرویس ماهانه آسانسور | D10: سرویس آسانسور | E10: آسانسور نمونه | F10: 6000000 | G10: وزنی | H10: عملیاتی | I10: 1405-07 | J10: =SUMIFS('پرداخت‌ها'!$C$5:$C$34,'پرداخت‌ها'!$B$5:$B$34,A10) | K10: =N(F10)-J10 | L10: =IF(N(F10)=0,"",IF(J10=0,"پرداخت‌نشده",IF(J10<F10,"پرداخت جزئی",IF(J10=F10,"پرداخت‌شده","پرداخت مازاد!"))))
A11: E7 | B11: 1405/07/20 | C11: تعمیر درب ورودی واحدها | D11: تعمیرات اختصاصی | E11: تعمیرکار نمونه | F11: 2500000 | G11: مبلغ صریح | H11: عملیاتی | I11: 1405-07 | J11: =SUMIFS('پرداخت‌ها'!$C$5:$C$34,'پرداخت‌ها'!$B$5:$B$34,A11) | K11: =N(F11)-J11 | L11: =IF(N(F11)=0,"",IF(J11=0,"پرداخت‌نشده",IF(J11<F11,"پرداخت جزئی",IF(J11=F11,"پرداخت‌شده","پرداخت مازاد!"))))
A12: E8 | B12: 1405/07/22 | C12: تعمیر اضطراری لوله اصلی | D12: تعمیرات اضطراری | E12: لوله‌کش نمونه | F12: 3000000 | G12: بدون تسهیم (صندوق) | H12: اندوخته | I12: 1405-07 | J12: =SUMIFS('پرداخت‌ها'!$C$5:$C$34,'پرداخت‌ها'!$B$5:$B$34,A12) | K12: =N(F12)-J12 | L12: =IF(N(F12)=0,"",IF(J12=0,"پرداخت‌نشده",IF(J12<F12,"پرداخت جزئی",IF(J12=F12,"پرداخت‌شده","پرداخت مازاد!"))))
A13: E9 | J13: =SUMIFS('پرداخت‌ها'!$C$5:$C$34,'پرداخت‌ها'!$B$5:$B$34,A13) | K13: =N(F13)-J13 | L13: =IF(N(F13)=0,"",IF(J13=0,"پرداخت‌نشده",IF(J13<F13,"پرداخت جزئی",IF(J13=F13,"پرداخت‌شده","پرداخت مازاد!"))))
A14: E10 | J14: =SUMIFS('پرداخت‌ها'!$C$5:$C$34,'پرداخت‌ها'!$B$5:$B$34,A14) | K14: =N(F14)-J14 | L14: =IF(N(F14)=0,"",IF(J14=0,"پرداخت‌نشده",IF(J14<F14,"پرداخت جزئی",IF(J14=F14,"پرداخت‌شده","پرداخت مازاد!"))))
A15: E11 | J15: =SUMIFS('پرداخت‌ها'!$C$5:$C$34,'پرداخت‌ها'!$B$5:$B$34,A15) | K15: =N(F15)-J15 | L15: =IF(N(F15)=0,"",IF(J15=0,"پرداخت‌نشده",IF(J15<F15,"پرداخت جزئی",IF(J15=F15,"پرداخت‌شده","پرداخت مازاد!"))))
A16: E12 | J16: =SUMIFS('پرداخت‌ها'!$C$5:$C$34,'پرداخت‌ها'!$B$5:$B$34,A16) | K16: =N(F16)-J16 | L16: =IF(N(F16)=0,"",IF(J16=0,"پرداخت‌نشده",IF(J16<F16,"پرداخت جزئی",IF(J16=F16,"پرداخت‌شده","پرداخت مازاد!"))))
C17: جمع | F17: =SUM(F5:F16) | J17: =SUM(J5:J16) | K17: =SUM(K5:K16)

Sheet اقلام شارژ
A1: اقلام شارژ دوره‌ای (مثل حق اندوخته)
A2: این اقلام هزینه نیستند؛ مستقیماً به واحدها شارژ می‌شوند.
A4: شناسه | B4: عنوان | C4: دسته | D4: صندوق | E4: مبلغ کل (ریال) | F4: مبنای تسهیم | G4: فعال
A5: C1 | B5: حق اندوخته ماهانه | C5: اندوخته | D5: اندوخته | E5: 9000000 | F5: مساوی | G5: بله
A6: C2
A7: C3
A8: C4
A9: C5

Sheet شمول
A1: شمول واحدها در هر هزینه/قلم (۱ = مشمول، ۰ = مستثنا)
A2: برای تسهیم میان زیرمجموعه‌ای از واحدها، واحدهای غیرمشمول را ۰ کنید.
A4: منبع | B4: 1-1 | C4: 1-2 | D4: 1-3 | E4: 2-1 | F4: 2-2 | G4: 3-1 | H4: 3-2 | I4: 4-1 | J4: 4-2 | K4: جمع ردیف
A5: E1 | B5: 1 | C5: 1 | D5: 1 | E5: 1 | F5: 1 | G5: 1 | H5: 1 | I5: 1 | J5: 1 | K5: =SUM(B5:J5)
A6: E2 | B6: 1 | C6: 1 | D6: 1 | E6: 1 | F6: 1 | G6: 1 | H6: 1 | I6: 1 | J6: 1 | K6: =SUM(B6:J6)
A7: E3 | B7: 1 | C7: 1 | D7: 1 | E7: 1 | F7: 1 | G7: 1 | H7: 1 | I7: 1 | J7: 1 | K7: =SUM(B7:J7)
A8: E4 | B8: 1 | C8: 1 | D8: 1 | E8: 1 | F8: 1 | G8: 1 | H8: 1 | I8: 1 | J8: 1 | K8: =SUM(B8:J8)
A9: E5 | B9: 1 | C9: 1 | D9: 1 | E9: 1 | F9: 1 | G9: 1 | H9: 1 | I9: 1 | J9: 1 | K9: =SUM(B9:J9)
A10: E6 | B10: 1 | C10: 1 | D10: 1 | E10: 1 | F10: 1 | G10: 1 | H10: 1 | I10: 1 | J10: 1 | K10: =SUM(B10:J10)
A11: E7 | B11: 1 | C11: 1 | D11: 1 | E11: 1 | F11: 1 | G11: 1 | H11: 1 | I11: 1 | J11: 1 | K11: =SUM(B11:J11)
A12: E8 | B12: 1 | C12: 1 | D12: 1 | E12: 1 | F12: 1 | G12: 1 | H12: 1 | I12: 1 | J12: 1 | K12: =SUM(B12:J12)
A13: E9 | B13: 1 | C13: 1 | D13: 1 | E13: 1 | F13: 1 | G13: 1 | H13: 1 | I13: 1 | J13: 1 | K13: =SUM(B13:J13)
A14: E10 | B14: 1 | C14: 1 | D14: 1 | E14: 1 | F14: 1 | G14: 1 | H14: 1 | I14: 1 | J14: 1 | K14: =SUM(B14:J14)
A15: E11 | B15: 1 | C15: 1 | D15: 1 | E15: 1 | F15: 1 | G15: 1 | H15: 1 | I15: 1 | J15: 1 | K15: =SUM(B15:J15)
A16: E12 | B16: 1 | C16: 1 | D16: 1 | E16: 1 | F16: 1 | G16: 1 | H16: 1 | I16: 1 | J16: 1 | K16: =SUM(B16:J16)
... A21: C5 | B21: 1 | C21: 1 | D21: 1 | E21: 1 | F21: 1 | G21: 1 | H21: 1 | I21: 1 | J21: 1 | K21: =SUM(B21:J21)

Sheet وزن‌ها
A1: وزن یا مبلغ صریح هر واحد (فقط برای مبنای «وزنی» و «مبلغ صریح»)
A2: وزن‌های آسانسور نمونه‌اند (طبقه اول ۰). در «مبلغ صریح» جمع ردیف باید برابر مبلغ هزینه باشد.
A4: منبع | B4: 1-1 | C4: 1-2 | D4: 1-3 | E4: 2-1 | F4: 2-2 | G4: 3-1 | H4: 3-2 | I4: 4-1 | J4: 4-2 | K4: جمع ردیف
A5: E1 | B5: 0 | C5: 0 | D5: 0 | E5: 0 | F5: 0 | G5: 0 | H5: 0 | I5: 0 | J5: 0 | K5: =SUM(B5:J5)
A6: E2 | B6: 0 | C6: 0 | D6: 0 | E6: 0 | F6: 0 | G6: 0 | H6: 0 | I6: 0 | J6: 0 | K6: =SUM(B6:J6)
A7: E3 | B7: 0 | C7: 0 | D7: 0 | E7: 0 | F7: 0 | G7: 0 | H7: 0 | I7: 0 | J7: 0 | K7: =SUM(B7:J7)
A8: E4 | B8: 0 | C8: 0 | D8: 0 | E8: 0 | F8: 0 | G8: 0 | H8: 0 | I8: 0 | J8: 0 | K8: =SUM(B8:J8)
A9: E5 | B9: 0 | C9: 0 | D9: 0 | E9: 0 | F9: 0 | G9: 0 | H9: 0 | I9: 0 | J9: 0 | K9: =SUM(B9:J9)
A10: E6 | B10: 0 | C10: 0 | D10: 0 | E10: 1 | F10: 1 | G10: 2 | H10: 2 | I10: 3 | J10: 3 | K10: =SUM(B10:J10)
A11: E7 | B11: 0 | C11: 0 | D11: 0 | E11: 1500000 | F11: 0 | G11: 0 | H11: 0 | I11: 0 | J11: 1000000 | K11: =SUM(B11:J11)
A12: E8 | B12: 0 | C12: 0 | D12: 0 | E12: 0 | F12: 0 | G12: 0 | H12: 0 | I12: 0 | J12: 0 | K12: =SUM(B12:J12)
A13: E9 | B13: 0 | C13: 0 | D13: 0 | E13: 0 | F13: 0 | G13: 0 | H13: 0 | I13: 0 | J13: 0 | K13: =SUM(B13:J13)
A14: E10 | B14: 0 | C14: 0 | D14: 0 | E14: 0 | F14: 0 | G14: 0 | H14: 0 | I14: 0 | J14: 0 | K14: =SUM(B14:J14)
A15: E11 | B15: 0 | C15: 0 | D15: 0 | E15: 0 | F15: 0 | G15: 0 | H15: 0 | I15: 0 | J15: 0 | K15: =SUM(B15:J15)
A16: E12 | B16: 0 | C16: 0 | D16: 0 | E16: 0 | F16: 0 | G16: 0 | H16: 0 | I16: 0 | J16: 0 | K16: =SUM(B16:J16)
... A21: C5 | B21: 0 | C21: 0 | D21: 0 | E21: 0 | F21: 0 | G21: 0 | H21: 0 | I21: 0 | J21: 0 | K21: =SUM(B21:J21)

Sheet سطرهای تسهیم
A1: سطرهای تسهیم (مشتق از هزینه‌ها و اقلام شارژ)
A2: هر هزینه یک سطر اصلی و یک سطر «سهم مشترک آب» دارد که فقط برای مبنای «مصرف + سهم مشترک» مقدار می‌گیرد.
A4: سطر | B4: منبع | C4: شرح | D4: مبنا | E4: مبلغ قابل تسهیم | F4: صندوق | G4: دسته | H4: ردیف ماتریس | I4: مجموع وزن
A5: L1 | B5: ='هزینه‌ها'!A5 | C5: =IF('هزینه‌ها'!C5="","",'هزینه‌ها'!C5) | D5: =IF('هزینه‌ها'!G5="مصرف + سهم مشترک","مصرف",IF('هزینه‌ها'!G5="","بدون تسهیم (صندوق)",'هزینه‌ها'!G5)) | E5: =IF(OR('هزینه‌ها'!G5="بدون تسهیم (صندوق)",'هزینه‌ها'!G5=""),0,IF('هزینه‌ها'!G5="مصرف + سهم مشترک",IF('کنتورها'!$M$5=0,0,ROUND(N('هزینه‌ها'!F5)*'کنتورها'!$M$6*1000/('کنتورها'!$M$5*1000*'تنظیمات'!$B$7),0)*'تنظیمات'!$B$7),N('هزینه‌ها'!F5))) | F5: ='هزینه‌ها'!H5 | G5: ='هزینه‌ها'!D5 | H5: 5 | I5: =SUMIFS('محاسبه تسهیم'!$I$5:$I$265,'محاسبه تسهیم'!$A$5:$A$265,A5)
A6: L2 | B6: ='هزینه‌ها'!A5 | C6: =IF('هزینه‌ها'!G5="مصرف + سهم مشترک","سهم مشترک آب: "&'هزینه‌ها'!C5,"") | D6: ='تنظیمات'!$B$12 | E6: =IF('هزینه‌ها'!G5="مصرف + سهم مشترک",N('هزینه‌ها'!F5)-E5,0) | F6: ='هزینه‌ها'!H5 | G6: ='هزینه‌ها'!D5 | H6: 5 | I6: =SUMIFS('محاسبه تسهیم'!$I$5:$I$265,'محاسبه تسهیم'!$A$5:$A$265,A6)
A7: L3 | B7: ='هزینه‌ها'!A6 | C7: =IF('هزینه‌ها'!C6="","",'هزینه‌ها'!C6) | D7: =IF('هزینه‌ها'!G6="مصرف + سهم مشترک","مصرف",IF('هزینه‌ها'!G6="","بدون تسهیم (صندوق)",'هزینه‌ها'!G6)) | E7: =IF(OR('هزینه‌ها'!G6="بدون تسهیم (صندوق)",'هزینه‌ها'!G6=""),0,IF('هزینه‌ها'!G6="مصرف + سهم مشترک",IF('کنتورها'!$M$5=0,0,ROUND(N('هزینه‌ها'!F6)*'کنتورها'!$M$6*1000/('کنتورها'!$M$5*1000*'تنظیمات'!$B$7),0)*'تنظیمات'!$B$7),N('هزینه‌ها'!F6))) | F7: ='هزینه‌ها'!H6 | G7: ='هزینه‌ها'!D6 | H7: 6 | I7: =SUMIFS('محاسبه تسهیم'!$I$5:$I$265,'محاسبه تسهیم'!$A$5:$A$265,A7)
A8: L4 | B8: ='هزینه‌ها'!A6 | C8: =IF('هزینه‌ها'!G6="مصرف + سهم مشترک","سهم مشترک آب: "&'هزینه‌ها'!C6,"") | D8: ='تنظیمات'!$B$12 | E8: =IF('هزینه‌ها'!G6="مصرف + سهم مشترک",N('هزینه‌ها'!F6)-E7,0) | F8: ='هزینه‌ها'!H6 | G8: ='هزینه‌ها'!D6 | H8: 6 | I8: =SUMIFS('محاسبه تسهیم'!$I$5:$I$265,'محاسبه تسهیم'!$A$5:$A$265,A8)
A9: L5 | B9: ='هزینه‌ها'!A7 | C9: =IF('هزینه‌ها'!C7="","",'هزینه‌ها'!C7) | D9: =IF('هزینه‌ها'!G7="مصرف + سهم مشترک","مصرف",IF('هزینه‌ها'!G7="","بدون تسهیم (صندوق)",'هزینه‌ها'!G7)) | E9: =IF(OR('هزینه‌ها'!G7="بدون تسهیم (صندوق)",'هزینه‌ها'!G7=""),0,IF('هزینه‌ها'!G7="مصرف + سهم مشترک",IF('کنتورها'!$M$5=0,0,ROUND(N('هزینه‌ها'!F7)*'کنتورها'!$M$6*1000/('کنتورها'!$M$5*1000*'تنظیمات'!$B$7),0)*'تنظیمات'!$B$7),N('هزینه‌ها'!F7))) | F9: ='هزینه‌ها'!H7 | G9: ='هزینه‌ها'!D7 | H9: 7 | I9: =SUMIFS('محاسبه تسهیم'!$I$5:$I$265,'محاسبه تسهیم'!$A$5:$A$265,A9)
A10: L6 | B10: ='هزینه‌ها'!A7 | C10: =IF('هزینه‌ها'!G7="مصرف + سهم مشترک","سهم مشترک آب: "&'هزینه‌ها'!C7,"") | D10: ='تنظیمات'!$B$12 | E10: =IF('هزینه‌ها'!G7="مصرف + سهم مشترک",N('هزینه‌ها'!F7)-E9,0) | F10: ='هزینه‌ها'!H7 | G10: ='هزینه‌ها'!D7 | H10: 7 | I10: =SUMIFS('محاسبه تسهیم'!$I$5:$I$265,'محاسبه تسهیم'!$A$5:$A$265,A10)
A11: L7 | B11: ='هزینه‌ها'!A8 | C11: =IF('هزینه‌ها'!C8="","",'هزینه‌ها'!C8) | D11: =IF('هزینه‌ها'!G8="مصرف + سهم مشترک","مصرف",IF('هزینه‌ها'!G8="","بدون تسهیم (صندوق)",'هزینه‌ها'!G8)) | E11: =IF(OR('هزینه‌ها'!G8="بدون تسهیم (صندوق)",'هزینه‌ها'!G8=""),0,IF('هزینه‌ها'!G8="مصرف + سهم مشترک",IF('کنتورها'!$M$5=0,0,ROUND(N('هزینه‌ها'!F8)*'کنتورها'!$M$6*1000/('کنتورها'!$M$5*1000*'تنظیمات'!$B$7),0)*'تنظیمات'!$B$7),N('هزینه‌ها'!F8))) | F11: ='هزینه‌ها'!H8 | G11: ='هزینه‌ها'!D8 | H11: 8 | I11: =SUMIFS('محاسبه تسهیم'!$I$5:$I$265,'محاسبه تسهیم'!$A$5:$A$265,A11)
A12: L8 | B12: ='هزینه‌ها'!A8 | C12: =IF('هزینه‌ها'!G8="مصرف + سهم مشترک","سهم مشترک آب: "&'هزینه‌ها'!C8,"") | D12: ='تنظیمات'!$B$12 | E12: =IF('هزینه‌ها'!G8="مصرف + سهم مشترک",N('هزینه‌ها'!F8)-E11,0) | F12: ='هزینه‌ها'!H8 | G12: ='هزینه‌ها'!D8 | H12: 8 | I12: =SUMIFS('محاسبه تسهیم'!$I$5:$I$265,'محاسبه تسهیم'!$A$5:$A$265,A12)
A13: L9 | B13: ='هزینه‌ها'!A9 | C13: =IF('هزینه‌ها'!C9="","",'هزینه‌ها'!C9) | D13: =IF('هزینه‌ها'!G9="مصرف + سهم مشترک","مصرف",IF('هزینه‌ها'!G9="","بدون تسهیم (صندوق)",'هزینه‌ها'!G9)) | E13: =IF(OR('هزینه‌ها'!G9="بدون تسهیم (صندوق)",'هزینه‌ها'!G9=""),0,IF('هزینه‌ها'!G9="مصرف + سهم مشترک",IF('کنتورها'!$M$5=0,0,ROUND(N('هزینه‌ها'!F9)*'کنتورها'!$M$6*1000/('کنتورها'!$M$5*1000*'تنظیمات'!$B$7),0)*'تنظیمات'!$B$7),N('هزینه‌ها'!F9))) | F13: ='هزینه‌ها'!H9 | G13: ='هزینه‌ها'!D9 | H13: 9 | I13: =SUMIFS('محاسبه تسهیم'!$I$5:$I$265,'محاسبه تسهیم'!$A$5:$A$265,A13)
A14: L10 | B14: ='هزینه‌ها'!A9 | C14: =IF('هزینه‌ها'!G9="مصرف + سهم مشترک","سهم مشترک آب: "&'هزینه‌ها'!C9,"") | D14: ='تنظیمات'!$B$12 | E14: =IF('هزینه‌ها'!G9="مصرف + سهم مشترک",N('هزینه‌ها'!F9)-E13,0) | F14: ='هزینه‌ها'!H9 | G14: ='هزینه‌ها'!D9 | H14: 9 | I14: =SUMIFS('محاسبه تسهیم'!$I$5:$I$265,'محاسبه تسهیم'!$A$5:$A$265,A14)
A15: L11 | B15: ='هزینه‌ها'!A10 | C15: =IF('هزینه‌ها'!C10="","",'هزینه‌ها'!C10) | D15: =IF('هزینه‌ها'!G10="مصرف + سهم مشترک","مصرف",IF('هزینه‌ها'!G10="","بدون تسهیم (صندوق)",'هزینه‌ها'!G10)) | E15: =IF(OR('هزینه‌ها'!G10="بدون تسهیم (صندوق)",'هزینه‌ها'!G10=""),0,IF('هزینه‌ها'!G10="مصرف + سهم مشترک",IF('کنتورها'!$M$5=0,0,ROUND(N('هزینه‌ها'!F10)*'کنتورها'!$M$6*1000/('کنتورها'!$M$5*1000*'تنظیمات'!$B$7),0)*'تنظیمات'!$B$7),N('هزینه‌ها'!F10))) | F15: ='هزینه‌ها'!H10 | G15: ='هزینه‌ها'!D10 | H15: 10 | I15: =SUMIFS('محاسبه تسهیم'!$I$5:$I$265,'محاسبه تسهیم'!$A$5:$A$265,A15)
A16: L12 | B16: ='هزینه‌ها'!A10 | C16: =IF('هزینه‌ها'!G10="مصرف + سهم مشترک","سهم مشترک آب: "&'هزینه‌ها'!C10,"") | D16: ='تنظیمات'!$B$12 | E16: =IF('هزینه‌ها'!G10="مصرف + سهم مشترک",N('هزینه‌ها'!F10)-E15,0) | F16: ='هزینه‌ها'!H10 | G16: ='هزینه‌ها'!D10 | H16: 10 | I16: =SUMIFS('محاسبه تسهیم'!$I$5:$I$265,'محاسبه تسهیم'!$A$5:$A$265,A16)
A17: L13 | B17: ='هزینه‌ها'!A11 | C17: =IF('هزینه‌ها'!C11="","",'هزینه‌ها'!C11) | D17: =IF('هزینه‌ها'!G11="مصرف + سهم مشترک","مصرف",IF('هزینه‌ها'!G11="","بدون تسهیم (صندوق)",'هزینه‌ها'!G11)) | E17: =IF(OR('هزینه‌ها'!G11="بدون تسهیم (صندوق)",'هزینه‌ها'!G11=""),0,IF('هزینه‌ها'!G11="مصرف + سهم مشترک",IF('کنتورها'!$M$5=0,0,ROUND(N('هزینه‌ها'!F11)*'کنتورها'!$M$6*1000/('کنتورها'!$M$5*1000*'تنظیمات'!$B$7),0)*'تنظیمات'!$B$7),N('هزینه‌ها'!F11))) | F17: ='هزینه‌ها'!H11 | G17: ='هزینه‌ها'!D11 | H17: 11 | I17: =SUMIFS('محاسبه تسهیم'!$I$5:$I$265,'محاسبه تسهیم'!$A$5:$A$265,A17)
A18: L14 | B18: ='هزینه‌ها'!A11 | C18: =IF('هزینه‌ها'!G11="مصرف + سهم مشترک","سهم مشترک آب: "&'هزینه‌ها'!C11,"") | D18: ='تنظیمات'!$B$12 | E18: =IF('هزینه‌ها'!G11="مصرف + سهم مشترک",N('هزینه‌ها'!F11)-E17,0) | F18: ='هزینه‌ها'!H11 | G18: ='هزینه‌ها'!D11 | H18: 11 | I18: =SUMIFS('محاسبه تسهیم'!$I$5:$I$265,'محاسبه تسهیم'!$A$5:$A$265,A18)
A19: L15 | B19: ='هزینه‌ها'!A12 | C19: =IF('هزینه‌ها'!C12="","",'هزینه‌ها'!C12) | D19: =IF('هزینه‌ها'!G12="مصرف + سهم مشترک","مصرف",IF('هزینه‌ها'!G12="","بدون تسهیم (صندوق)",'هزینه‌ها'!G12)) | E19: =IF(OR('هزینه‌ها'!G12="بدون تسهیم (صندوق)",'هزینه‌ها'!G12=""),0,IF('هزینه‌ها'!G12="مصرف + سهم مشترک",IF('کنتورها'!$M$5=0,0,ROUND(N('هزینه‌ها'!F12)*'کنتورها'!$M$6*1000/('کنتورها'!$M$5*1000*'تنظیمات'!$B$7),0)*'تنظیمات'!$B$7),N('هزینه‌ها'!F12))) | F19: ='هزینه‌ها'!H12 | G19: ='هزینه‌ها'!D12 | H19: 12 | I19: =SUMIFS('محاسبه تسهیم'!$I$5:$I$265,'محاسبه تسهیم'!$A$5:$A$265,A19)
A20: L16 | B20: ='هزینه‌ها'!A12 | C20: =IF('هزینه‌ها'!G12="مصرف + سهم مشترک","سهم مشترک آب: "&'هزینه‌ها'!C12,"") | D20: ='تنظیمات'!$B$12 | E20: =IF('هزینه‌ها'!G12="مصرف + سهم مشترک",N('هزینه‌ها'!F12)-E19,0) | F20: ='هزینه‌ها'!H12 | G20: ='هزینه‌ها'!D12 | H20: 12 | I20: =SUMIFS('محاسبه تسهیم'!$I$5:$I$265,'محاسبه تسهیم'!$A$5:$A$265,A20)
A21: L17 | B21: ='هزینه‌ها'!A13 | C21: =IF('هزینه‌ها'!C13="","",'هزینه‌ها'!C13) | D21: =IF('هزینه‌ها'!G13="مصرف + سهم مشترک","مصرف",IF('هزینه‌ها'!G13="","بدون تسهیم (صندوق)",'هزینه‌ها'!G13)) | E21: =IF(OR('هزینه‌ها'!G13="بدون تسهیم (صندوق)",'هزینه‌ها'!G13=""),0,IF('هزینه‌ها'!G13="مصرف + سهم مشترک",IF('کنتورها'!$M$5=0,0,ROUND(N('هزینه‌ها'!F13)*'کنتورها'!$M$6*1000/('کنتورها'!$M$5*1000*'تنظیمات'!$B$7),0)*'تنظیمات'!$B$7),N('هزینه‌ها'!F13))) | F21: ='هزینه‌ها'!H13 | G21: ='هزینه‌ها'!D13 | H21: 13 | I21: =SUMIFS('محاسبه تسهیم'!$I$5:$I$265,'محاسبه تسهیم'!$A$5:$A$265,A21)
A22: L18 | B22: ='هزینه‌ها'!A13 | C22: =IF('هزینه‌ها'!G13="مصرف + سهم مشترک","سهم مشترک آب: "&'هزینه‌ها'!C13,"") | D22: ='تنظیمات'!$B$12 | E22: =IF('هزینه‌ها'!G13="مصرف + سهم مشترک",N('هزینه‌ها'!F13)-E21,0) | F22: ='هزینه‌ها'!H13 | G22: ='هزینه‌ها'!D13 | H22: 13 | I22: =SUMIFS('محاسبه تسهیم'!$I$5:$I$265,'محاسبه تسهیم'!$A$5:$A$265,A22)
A23: L19 | B23: ='هزینه‌ها'!A14 | C23: =IF('هزینه‌ها'!C14="","",'هزینه‌ها'!C14) | D23: =IF('هزینه‌ها'!G14="مصرف + سهم مشترک","مصرف",IF('هزینه‌ها'!G14="","بدون تسهیم (صندوق)",'هزینه‌ها'!G14)) | E23: =IF(OR('هزینه‌ها'!G14="بدون تسهیم (صندوق)",'هزینه‌ها'!G14=""),0,IF('هزینه‌ها'!G14="مصرف + سهم مشترک",IF('کنتورها'!$M$5=0,0,ROUND(N('هزینه‌ها'!F14)*'کنتورها'!$M$6*1000/('کنتورها'!$M$5*1000*'تنظیمات'!$B$7),0)*'تنظیمات'!$B$7),N('هزینه‌ها'!F14))) | F23: ='هزینه‌ها'!H14 | G23: ='هزینه‌ها'!D14 | H23: 14 | I23: =SUMIFS('محاسبه تسهیم'!$I$5:$I$265,'محاسبه تسهیم'!$A$5:$A$265,A23)
A24: L20 | B24: ='هزینه‌ها'!A14 | C24: =IF('هزینه‌ها'!G14="مصرف + سهم مشترک","سهم مشترک آب: "&'هزینه‌ها'!C14,"") | D24: ='تنظیمات'!$B$12 | E24: =IF('هزینه‌ها'!G14="مصرف + سهم مشترک",N('هزینه‌ها'!F14)-E23,0) | F24: ='هزینه‌ها'!H14 | G24: ='هزینه‌ها'!D14 | H24: 14 | I24: =SUMIFS('محاسبه تسهیم'!$I$5:$I$265,'محاسبه تسهیم'!$A$5:$A$265,A24)
A25: L21 | B25: ='هزینه‌ها'!A15 | C25: =IF('هزینه‌ها'!C15="","",'هزینه‌ها'!C15) | D25: =IF('هزینه‌ها'!G15="مصرف + سهم مشترک","مصرف",IF('هزینه‌ها'!G15="","بدون تسهیم (صندوق)",'هزینه‌ها'!G15)) | E25: =IF(OR('هزینه‌ها'!G15="بدون تسهیم (صندوق)",'هزینه‌ها'!G15=""),0,IF('هزینه‌ها'!G15="مصرف + سهم مشترک",IF('کنتورها'!$M$5=0,0,ROUND(N('هزینه‌ها'!F15)*'کنتورها'!$M$6*1000/('کنتورها'!$M$5*1000*'تنظیمات'!$B$7),0)*'تنظیمات'!$B$7),N('هزینه‌ها'!F15))) | F25: ='هزینه‌ها'!H15 | G25: ='هزینه‌ها'!D15 | H25: 15 | I25: =SUMIFS('محاسبه تسهیم'!$I$5:$I$265,'محاسبه تسهیم'!$A$5:$A$265,A25)
A26: L22 | B26: ='هزینه‌ها'!A15 | C26: =IF('هزینه‌ها'!G15="مصرف + سهم مشترک","سهم مشترک آب: "&'هزینه‌ها'!C15,"") | D26: ='تنظیمات'!$B$12 | E26: =IF('هزینه‌ها'!G15="مصرف + سهم مشترک",N('هزینه‌ها'!F15)-E25,0) | F26: ='هزینه‌ها'!H15 | G26: ='هزینه‌ها'!D15 | H26: 15 | I26: =SUMIFS('محاسبه تسهیم'!$I$5:$I$265,'محاسبه تسهیم'!$A$5:$A$265,A26)
A27: L23 | B27: ='هزینه‌ها'!A16 | C27: =IF('هزینه‌ها'!C16="","",'هزینه‌ها'!C16) | D27: =IF('هزینه‌ها'!G16="مصرف + سهم مشترک","مصرف",IF('هزینه‌ها'!G16="","بدون تسهیم (صندوق)",'هزینه‌ها'!G16)) | E27: =IF(OR('هزینه‌ها'!G16="بدون تسهیم (صندوق)",'هزینه‌ها'!G16=""),0,IF('هزینه‌ها'!G16="مصرف + سهم مشترک",IF('کنتورها'!$M$5=0,0,ROUND(N('هزینه‌ها'!F16)*'کنتورها'!$M$6*1000/('کنتورها'!$M$5*1000*'تنظیمات'!$B$7),0)*'تنظیمات'!$B$7),N('هزینه‌ها'!F16))) | F27: ='هزینه‌ها'!H16 | G27: ='هزینه‌ها'!D16 | H27: 16 | I27: =SUMIFS('محاسبه تسهیم'!$I$5:$I$265,'محاسبه تسهیم'!$A$5:$A$265,A27)
A28: L24 | B28: ='هزینه‌ها'!A16 | C28: =IF('هزینه‌ها'!G16="مصرف + سهم مشترک","سهم مشترک آب: "&'هزینه‌ها'!C16,"") | D28: ='تنظیمات'!$B$12 | E28: =IF('هزینه‌ها'!G16="مصرف + سهم مشترک",N('هزینه‌ها'!F16)-E27,0) | F28: ='هزینه‌ها'!H16 | G28: ='هزینه‌ها'!D16 | H28: 16 | I28: =SUMIFS('محاسبه تسهیم'!$I$5:$I$265,'محاسبه تسهیم'!$A$5:$A$265,A28)
A29: L25 | B29: ='اقلام شارژ'!A5 | C29: =IF('اقلام شارژ'!B5="","",'اقلام شارژ'!B5) | D29: =IF('اقلام شارژ'!F5="","بدون تسهیم (صندوق)",'اقلام شارژ'!F5) | E29: =IF('اقلام شارژ'!G5="بله",N('اقلام شارژ'!E5),0) | F29: ='اقلام شارژ'!D5 | G29: ='اقلام شارژ'!C5 | H29: 17 | I29: =SUMIFS('محاسبه تسهیم'!$I$5:$I$265,'محاسبه تسهیم'!$A$5:$A$265,A29)
A30: L26 | B30: ='اقلام شارژ'!A6 | C30: =IF('اقلام شارژ'!B6="","",'اقلام شارژ'!B6) | D30: =IF('اقلام شارژ'!F6="","بدون تسهیم (صندوق)",'اقلام شارژ'!F6) | E30: =IF('اقلام شارژ'!G6="بله",N('اقلام شارژ'!E6),0) | F30: ='اقلام شارژ'!D6 | G30: ='اقلام شارژ'!C6 | H30: 18 | I30: =SUMIFS('محاسبه تسهیم'!$I$5:$I$265,'محاسبه تسهیم'!$A$5:$A$265,A30)
A31: L27 | B31: ='اقلام شارژ'!A7 | C31: =IF('اقلام شارژ'!B7="","",'اقلام شارژ'!B7) | D31: =IF('اقلام شارژ'!F7="","بدون تسهیم (صندوق)",'اقلام شارژ'!F7) | E31: =IF('اقلام شارژ'!G7="بله",N('اقلام شارژ'!E7),0) | F31: ='اقلام شارژ'!D7 | G31: ='اقلام شارژ'!C7 | H31: 19 | I31: =SUMIFS('محاسبه تسهیم'!$I$5:$I$265,'محاسبه تسهیم'!$A$5:$A$265,A31)
A32: L28 | B32: ='اقلام شارژ'!A8 | C32: =IF('اقلام شارژ'!B8="","",'اقلام شارژ'!B8) | D32: =IF('اقلام شارژ'!F8="","بدون تسهیم (صندوق)",'اقلام شارژ'!F8) | E32: =IF('اقلام شارژ'!G8="بله",N('اقلام شارژ'!E8),0) | F32: ='اقلام شارژ'!D8 | G32: ='اقلام شارژ'!C8 | H32: 20 | I32: =SUMIFS('محاسبه تسهیم'!$I$5:$I$265,'محاسبه تسهیم'!$A$5:$A$265,A32)
A33: L29 | B33: ='اقلام شارژ'!A9 | C33: =IF('اقلام شارژ'!B9="","",'اقلام شارژ'!B9) | D33: =IF('اقلام شارژ'!F9="","بدون تسهیم (صندوق)",'اقلام شارژ'!F9) | E33: =IF('اقلام شارژ'!G9="بله",N('اقلام شارژ'!E9),0) | F33: ='اقلام شارژ'!D9 | G33: ='اقلام شارژ'!C9 | H33: 21 | I33: =SUMIFS('محاسبه تسهیم'!$I$5:$I$265,'محاسبه تسهیم'!$A$5:$A$265,A33)

Sheet محاسبه تسهیم
A1: محاسبه سهم هر واحد — روش بزرگ‌ترین باقیمانده
A2: باقیمانده (عدد صحیح) = مبلغ×وزن − مجموع‌وزن×واحدگرد×⌊مبلغ×وزن÷(مجموع‌وزن×واحدگرد)⌋ ؛ رتبه بر اساس باقیمانده نزولی و سپس ترتیب واحد.
A4: سطر | B4: منبع | C4: واحد | D4: ترتیب | E4: مبنا | F4: مبلغ سطر | G4: مشمول | H4: کمیت مبنا | I4: وزن | J4: مجموع وزن | K4: سهم پایه | L4: باقیمانده | M4: رتبه | N4: باقیمانده کل | O4: تعداد افزایش | P4: خرده نهایی | Q4: سهم نهایی | R4: صندوق | S4: دسته | T4: آب؟
A5: ='سطرهای تسهیم'!A5 | B5: ='سطرهای تسهیم'!B5 | C5: ='واحدها'!A5 | D5: ='واحدها'!H5 | E5: ='سطرهای تسهیم'!D5 | F5: ='سطرهای تسهیم'!E5 | G5: =IF('واحدها'!F5="بله",'شمول'!B5,0) | H5: =CHOOSE(MATCH(E5,'فهرست‌ها'!$A$4:$A$13,0),1,'واحدها'!E5,'واحدها'!D5*100,'واحدها'!J5,'واحدها'!J5,'وزن‌ها'!B5,'وزن‌ها'!B5,'واحدها'!K5,'واحدها'!L5,0) | I5: =G5*H5 | J5: =SUMIFS($I$5:$I$265,$A$5:$A$265,A5) | K5: =IF(J5=0,0,'تنظیمات'!$B$7*INT(F5*I5/(J5*'تنظیمات'!$B$7))) | L5: =IF(J5=0,0,F5*I5-J5*'تنظیمات'!$B$7*INT(F5*I5/(J5*'تنظیمات'!$B$7))) | M5: =1+COUNTIFS($A$5:$A$265,A5,$L$5:$L$265,">"&L5)+COUNTIFS($A$5:$A$265,A5,$L$5:$L$265,L5,$D$5:$D$265,"<"&D5) | N5: =IF(J5=0,0,F5-SUMIFS($K$5:$K$265,$A$5:$A$265,A5)) | O5: =INT(N5/'تنظیمات'!$B$7) | P5: =N5-O5*'تنظیمات'!$B$7 | Q5: =IF(J5=0,0,K5+IF(M5<=O5,'تنظیمات'!$B$7,0)+IF(M5=1,P5,0)) | R5: ='سطرهای تسهیم'!F5 | S5: ='سطرهای تسهیم'!G5 | T5: =IFERROR(INDEX('دسته‌ها'!$D$5:$D$25,MATCH(S5,'دسته‌ها'!$A$5:$A$25,0)),"خیر")
A6: ='سطرهای تسهیم'!A5 | B6: ='سطرهای تسهیم'!B5 | C6: ='واحدها'!A6 | D6: ='واحدها'!H6 | E6: ='سطرهای تسهیم'!D5 | F6: ='سطرهای تسهیم'!E5 | G6: =IF('واحدها'!F6="بله",'شمول'!C5,0) | H6: =CHOOSE(MATCH(E6,'فهرست‌ها'!$A$4:$A$13,0),1,'واحدها'!E6,'واحدها'!D6*100,'واحدها'!J6,'واحدها'!J6,'وزن‌ها'!C5,'وزن‌ها'!C5,'واحدها'!K6,'واحدها'!L6,0) | I6: =G6*H6 | J6: =SUMIFS($I$5:$I$265,$A$5:$A$265,A6) | K6: =IF(J6=0,0,'تنظیمات'!$B$7*INT(F6*I6/(J6*'تنظیمات'!$B$7))) | L6: =IF(J6=0,0,F6*I6-J6*'تنظیمات'!$B$7*INT(F6*I6/(J6*'تنظیمات'!$B$7))) | M6: =1+COUNTIFS($A$5:$A$265,A6,$L$5:$L$265,">"&L6)+COUNTIFS($A$5:$A$265,A6,$L$5:$L$265,L6,$D$5:$D$265,"<"&D6) | N6: =IF(J6=0,0,F6-SUMIFS($K$5:$K$265,$A$5:$A$265,A6)) | O6: =INT(N6/'تنظیمات'!$B$7) | P6: =N6-O6*'تنظیمات'!$B$7 | Q6: =IF(J6=0,0,K6+IF(M6<=O6,'تنظیمات'!$B$7,0)+IF(M6=1,P6,0)) | R6: ='سطرهای تسهیم'!F5 | S6: ='سطرهای تسهیم'!G5 | T6: =IFERROR(INDEX('دسته‌ها'!$D$5:$D$25,MATCH(S6,'دسته‌ها'!$A$5:$A$25,0)),"خیر")
A7: ='سطرهای تسهیم'!A5 | B7: ='سطرهای تسهیم'!B5 | C7: ='واحدها'!A7 | D7: ='واحدها'!H7 | E7: ='سطرهای تسهیم'!D5 | F7: ='سطرهای تسهیم'!E5 | G7: =IF('واحدها'!F7="بله",'شمول'!D5,0) | H7: =CHOOSE(MATCH(E7,'فهرست‌ها'!$A$4:$A$13,0),1,'واحدها'!E7,'واحدها'!D7*100,'واحدها'!J7,'واحدها'!J7,'وزن‌ها'!D5,'وزن‌ها'!D5,'واحدها'!K7,'واحدها'!L7,0) | I7: =G7*H7 | J7: =SUMIFS($I$5:$I$265,$A$5:$A$265,A7) | K7: =IF(J7=0,0,'تنظیمات'!$B$7*INT(F7*I7/(J7*'تنظیمات'!$B$7))) | L7: =IF(J7=0,0,F7*I7-J7*'تنظیمات'!$B$7*INT(F7*I7/(J7*'تنظیمات'!$B$7))) | M7: =1+COUNTIFS($A$5:$A$265,A7,$L$5:$L$265,">"&L7)+COUNTIFS($A$5:$A$265,A7,$L$5:$L$265,L7,$D$5:$D$265,"<"&D7) | N7: =IF(J7=0,0,F7-SUMIFS($K$5:$K$265,$A$5:$A$265,A7)) | O7: =INT(N7/'تنظیمات'!$B$7) | P7: =N7-O7*'تنظیمات'!$B$7 | Q7: =IF(J7=0,0,K7+IF(M7<=O7,'تنظیمات'!$B$7,0)+IF(M7=1,P7,0)) | R7: ='سطرهای تسهیم'!F5 | S7: ='سطرهای تسهیم'!G5 | T7: =IFERROR(INDEX('دسته‌ها'!$D$5:$D$25,MATCH(S7,'دسته‌ها'!$A$5:$A$25,0)),"خیر")
A8: ='سطرهای تسهیم'!A5 | B8: ='سطرهای تسهیم'!B5 | C8: ='واحدها'!A8 | D8: ='واحدها'!H8 | E8: ='سطرهای تسهیم'!D5 | F8: ='سطرهای تسهیم'!E5 | G8: =IF('واحدها'!F8="بله",'شمول'!E5,0) | H8: =CHOOSE(MATCH(E8,'فهرست‌ها'!$A$4:$A$13,0),1,'واحدها'!E8,'واحدها'!D8*100,'واحدها'!J8,'واحدها'!J8,'وزن‌ها'!E5,'وزن‌ها'!E5,'واحدها'!K8,'واحدها'!L8,0) | I8: =G8*H8 | J8: =SUMIFS($I$5:$I$265,$A$5:$A$265,A8) | K8: =IF(J8=0,0,'تنظیمات'!$B$7*INT(F8*I8/(J8*'تنظیمات'!$B$7))) | L8: =IF(J8=0,0,F8*I8-J8*'تنظیمات'!$B$7*INT(F8*I8/(J8*'تنظیمات'!$B$7))) | M8: =1+COUNTIFS($A$5:$A$265,A8,$L$5:$L$265,">"&L8)+COUNTIFS($A$5:$A$265,A8,$L$5:$L$265,L8,$D$5:$D$265,"<"&D8) | N8: =IF(J8=0,0,F8-SUMIFS($K$5:$K$265,$A$5:$A$265,A8)) | O8: =INT(N8/'تنظیمات'!$B$7) | P8: =N8-O8*'تنظیمات'!$B$7 | Q8: =IF(J8=0,0,K8+IF(M8<=O8,'تنظیمات'!$B$7,0)+IF(M8=1,P8,0)) | R8: ='سطرهای تسهیم'!F5 | S8: ='سطرهای تسهیم'!G5 | T8: =IFERROR(INDEX('دسته‌ها'!$D$5:$D$25,MATCH(S8,'دسته‌ها'!$A$5:$A$25,0)),"خیر")
A9: ='سطرهای تسهیم'!A5 | B9: ='سطرهای تسهیم'!B5 | C9: ='واحدها'!A9 | D9: ='واحدها'!H9 | E9: ='سطرهای تسهیم'!D5 | F9: ='سطرهای تسهیم'!E5 | G9: =IF('واحدها'!F9="بله",'شمول'!F5,0) | H9: =CHOOSE(MATCH(E9,'فهرست‌ها'!$A$4:$A$13,0),1,'واحدها'!E9,'واحدها'!D9*100,'واحدها'!J9,'واحدها'!J9,'وزن‌ها'!F5,'وزن‌ها'!F5,'واحدها'!K9,'واحدها'!L9,0) | I9: =G9*H9 | J9: =SUMIFS($I$5:$I$265,$A$5:$A$265,A9) | K9: =IF(J9=0,0,'تنظیمات'!$B$7*INT(F9*I9/(J9*'تنظیمات'!$B$7))) | L9: =IF(J9=0,0,F9*I9-J9*'تنظیمات'!$B$7*INT(F9*I9/(J9*'تنظیمات'!$B$7))) | M9: =1+COUNTIFS($A$5:$A$265,A9,$L$5:$L$265,">"&L9)+COUNTIFS($A$5:$A$265,A9,$L$5:$L$265,L9,$D$5:$D$265,"<"&D9) | N9: =IF(J9=0,0,F9-SUMIFS($K$5:$K$265,$A$5:$A$265,A9)) | O9: =INT(N9/'تنظیمات'!$B$7) | P9: =N9-O9*'تنظیمات'!$B$7 | Q9: =IF(J9=0,0,K9+IF(M9<=O9,'تنظیمات'!$B$7,0)+IF(M9=1,P9,0)) | R9: ='سطرهای تسهیم'!F5 | S9: ='سطرهای تسهیم'!G5 | T9: =IFERROR(INDEX('دسته‌ها'!$D$5:$D$25,MATCH(S9,'دسته‌ها'!$A$5:$A$25,0)),"خیر")
A10: ='سطرهای تسهیم'!A5 | B10: ='سطرهای تسهیم'!B5 | C10: ='واحدها'!A10 | D10: ='واحدها'!H10 | E10: ='سطرهای تسهیم'!D5 | F10: ='سطرهای تسهیم'!E5 | G10: =IF('واحدها'!F10="بله",'شمول'!G5,0) | H10: =CHOOSE(MATCH(E10,'فهرست‌ها'!$A$4:$A$13,0),1,'واحدها'!E10,'واحدها'!D10*100,'واحدها'!J10,'واحدها'!J10,'وزن‌ها'!G5,'وزن‌ها'!G5,'واحدها'!K10,'واحدها'!L10,0) | I10: =G10*H10 | J10: =SUMIFS($I$5:$I$265,$A$5:$A$265,A10) | K10: =IF(J10=0,0,'تنظیمات'!$B$7*INT(F10*I10/(J10*'تنظیمات'!$B$7))) | L10: =IF(J10=0,0,F10*I10-J10*'تنظیمات'!$B$7*INT(F10*I10/(J10*'تنظیمات'!$B$7))) | M10: =1+COUNTIFS($A$5:$A$265,A10,$L$5:$L$265,">"&L10)+COUNTIFS($A$5:$A$265,A10,$L$5:$L$265,L10,$D$5:$D$265,"<"&D10) | N10: =IF(J10=0,0,F10-SUMIFS($K$5:$K$265,$A$5:$A$265,A10)) | O10: =INT(N10/'تنظیمات'!$B$7) | P10: =N10-O10*'تنظیمات'!$B$7 | Q10: =IF(J10=0,0,K10+IF(M10<=O10,'تنظیمات'!$B$7,0)+IF(M10=1,P10,0)) | R10: ='سطرهای تسهیم'!F5 | S10: ='سطرهای تسهیم'!G5 | T10: =IFERROR(INDEX('دسته‌ها'!$D$5:$D$25,MATCH(S10,'دسته‌ها'!$A$5:$A$25,0)),"خیر")
A11: ='سطرهای تسهیم'!A5 | B11: ='سطرهای تسهیم'!B5 | C11: ='واحدها'!A11 | D11: ='واحدها'!H11 | E11: ='سطرهای تسهیم'!D5 | F11: ='سطرهای تسهیم'!E5 | G11: =IF('واحدها'!F11="بله",'شمول'!H5,0) | H11: =CHOOSE(MATCH(E11,'فهرست‌ها'!$A$4:$A$13,0),1,'واحدها'!E11,'واحدها'!D11*100,'واحدها'!J11,'واحدها'!J11,'وزن‌ها'!H5,'وزن‌ها'!H5,'واحدها'!K11,'واحدها'!L11,0) | I11: =G11*H11 | J11: =SUMIFS($I$5:$I$265,$A$5:$A$265,A11) | K11: =IF(J11=0,0,'تنظیمات'!$B$7*INT(F11*I11/(J11*'تنظیمات'!$B$7))) | L11: =IF(J11=0,0,F11*I11-J11*'تنظیمات'!$B$7*INT(F11*I11/(J11*'تنظیمات'!$B$7))) | M11: =1+COUNTIFS($A$5:$A$265,A11,$L$5:$L$265,">"&L11)+COUNTIFS($A$5:$A$265,A11,$L$5:$L$265,L11,$D$5:$D$265,"<"&D11) | N11: =IF(J11=0,0,F11-SUMIFS($K$5:$K$265,$A$5:$A$265,A11)) | O11: =INT(N11/'تنظیمات'!$B$7) | P11: =N11-O11*'تنظیمات'!$B$7 | Q11: =IF(J11=0,0,K11+IF(M11<=O11,'تنظیمات'!$B$7,0)+IF(M11=1,P11,0)) | R11: ='سطرهای تسهیم'!F5 | S11: ='سطرهای تسهیم'!G5 | T11: =IFERROR(INDEX('دسته‌ها'!$D$5:$D$25,MATCH(S11,'دسته‌ها'!$A$5:$A$25,0)),"خیر")
A12: ='سطرهای تسهیم'!A5 | B12: ='سطرهای تسهیم'!B5 | C12: ='واحدها'!A12 | D12: ='واحدها'!H12 | E12: ='سطرهای تسهیم'!D5 | F12: ='سطرهای تسهیم'!E5 | G12: =IF('واحدها'!F12="بله",'شمول'!I5,0) | H12: =CHOOSE(MATCH(E12,'فهرست‌ها'!$A$4:$A$13,0),1,'واحدها'!E12,'واحدها'!D12*100,'واحدها'!J12,'واحدها'!J12,'وزن‌ها'!I5,'وزن‌ها'!I5,'واحدها'!K12,'واحدها'!L12,0) | I12: =G12*H12 | J12: =SUMIFS($I$5:$I$265,$A$5:$A$265,A12) | K12: =IF(J12=0,0,'تنظیمات'!$B$7*INT(F12*I12/(J12*'تنظیمات'!$B$7))) | L12: =IF(J12=0,0,F12*I12-J12*'تنظیمات'!$B$7*INT(F12*I12/(J12*'تنظیمات'!$B$7))) | M12: =1+COUNTIFS($A$5:$A$265,A12,$L$5:$L$265,">"&L12)+COUNTIFS($A$5:$A$265,A12,$L$5:$L$265,L12,$D$5:$D$265,"<"&D12) | N12: =IF(J12=0,0,F12-SUMIFS($K$5:$K$265,$A$5:$A$265,A12)) | O12: =INT(N12/'تنظیمات'!$B$7) | P12: =N12-O12*'تنظیمات'!$B$7 | Q12: =IF(J12=0,0,K12+IF(M12<=O12,'تنظیمات'!$B$7,0)+IF(M12=1,P12,0)) | R12: ='سطرهای تسهیم'!F5 | S12: ='سطرهای تسهیم'!G5 | T12: =IFERROR(INDEX('دسته‌ها'!$D$5:$D$25,MATCH(S12,'دسته‌ها'!$A$5:$A$25,0)),"خیر")
A13: ='سطرهای تسهیم'!A5 | B13: ='سطرهای تسهیم'!B5 | C13: ='واحدها'!A13 | D13: ='واحدها'!H13 | E13: ='سطرهای تسهیم'!D5 | F13: ='سطرهای تسهیم'!E5 | G13: =IF('واحدها'!F13="بله",'شمول'!J5,0) | H13: =CHOOSE(MATCH(E13,'فهرست‌ها'!$A$4:$A$13,0),1,'واحدها'!E13,'واحدها'!D13*100,'واحدها'!J13,'واحدها'!J13,'وزن‌ها'!J5,'وزن‌ها'!J5,'واحدها'!K13,'واحدها'!L13,0) | I13: =G13*H13 | J13: =SUMIFS($I$5:$I$265,$A$5:$A$265,A13) | K13: =IF(J13=0,0,'تنظیمات'!$B$7*INT(F13*I13/(J13*'تنظیمات'!$B$7))) | L13: =IF(J13=0,0,F13*I13-J13*'تنظیمات'!$B$7*INT(F13*I13/(J13*'تنظیمات'!$B$7))) | M13: =1+COUNTIFS($A$5:$A$265,A13,$L$5:$L$265,">"&L13)+COUNTIFS($A$5:$A$265,A13,$L$5:$L$265,L13,$D$5:$D$265,"<"&D13) | N13: =IF(J13=0,0,F13-SUMIFS($K$5:$K$265,$A$5:$A$265,A13)) | O13: =INT(N13/'تنظیمات'!$B$7) | P13: =N13-O13*'تنظیمات'!$B$7 | Q13: =IF(J13=0,0,K13+IF(M13<=O13,'تنظیمات'!$B$7,0)+IF(M13=1,P13,0)) | R13: ='سطرهای تسهیم'!F5 | S13: ='سطرهای تسهیم'!G5 | T13: =IFERROR(INDEX('دسته‌ها'!$D$5:$D$25,MATCH(S13,'دسته‌ها'!$A$5:$A$25,0)),"خیر")
A14: ='سطرهای تسهیم'!A6 | B14: ='سطرهای تسهیم'!B6 | C14: ='واحدها'!A5 | D14: ='واحدها'!H5 | E14: ='سطرهای تسهیم'!D6 | F14: ='سطرهای تسهیم'!E6 | G14: =IF('واحدها'!F5="بله",'شمول'!B5,0) | H14: =CHOOSE(MATCH(E14,'فهرست‌ها'!$A$4:$A$13,0),1,'واحدها'!E5,'واحدها'!D5*100,'واحدها'!J5,'واحدها'!J5,'وزن‌ها'!B5,'وزن‌ها'!B5,'واحدها'!K5,'واحدها'!L5,0) | I14: =G14*H14 | J14: =SUMIFS($I$5:$I$265,$A$5:$A$265,A14) | K14: =IF(J14=0,0,'تنظیمات'!$B$7*INT(F14*I14/(J14*'تنظیمات'!$B$7))) | L14: =IF(J14=0,0,F14*I14-J14*'تنظیمات'!$B$7*INT(F14*I14/(J14*'تنظیمات'!$B$7))) | M14: =1+COUNTIFS($A$5:$A$265,A14,$L$5:$L$265,">"&L14)+COUNTIFS($A$5:$A$265,A14,$L$5:$L$265,L14,$D$5:$D$265,"<"&D14) | N14: =IF(J14=0,0,F14-SUMIFS($K$5:$K$265,$A$5:$A$265,A14)) | O14: =INT(N14/'تنظیمات'!$B$7) | P14: =N14-O14*'تنظیمات'!$B$7 | Q14: =IF(J14=0,0,K14+IF(M14<=O14,'تنظیمات'!$B$7,0)+IF(M14=1,P14,0)) | R14: ='سطرهای تسهیم'!F6 | S14: ='سطرهای تسهیم'!G6 | T14: =IFERROR(INDEX('دسته‌ها'!$D$5:$D$25,MATCH(S14,'دسته‌ها'!$A$5:$A$25,0)),"خیر")
A15: ='سطرهای تسهیم'!A6 | B15: ='سطرهای تسهیم'!B6 | C15: ='واحدها'!A6 | D15: ='واحدها'!H6 | E15: ='سطرهای تسهیم'!D6 | F15: ='سطرهای تسهیم'!E6 | G15: =IF('واحدها'!F6="بله",'شمول'!C5,0) | H15: =CHOOSE(MATCH(E15,'فهرست‌ها'!$A$4:$A$13,0),1,'واحدها'!E6,'واحدها'!D6*100,'واحدها'!J6,'واحدها'!J6,'وزن‌ها'!C5,'وزن‌ها'!C5,'واحدها'!K6,'واحدها'!L6,0) | I15: =G15*H15 | J15: =SUMIFS($I$5:$I$265,$A$5:$A$265,A15) | K15: =IF(J15=0,0,'تنظیمات'!$B$7*INT(F15*I15/(J15*'تنظیمات'!$B$7))) | L15: =IF(J15=0,0,F15*I15-J15*'تنظیمات'!$B$7*INT(F15*I15/(J15*'تنظیمات'!$B$7))) | M15: =1+COUNTIFS($A$5:$A$265,A15,$L$5:$L$265,">"&L15)+COUNTIFS($A$5:$A$265,A15,$L$5:$L$265,L15,$D$5:$D$265,"<"&D15) | N15: =IF(J15=0,0,F15-SUMIFS($K$5:$K$265,$A$5:$A$265,A15)) | O15: =INT(N15/'تنظیمات'!$B$7) | P15: =N15-O15*'تنظیمات'!$B$7 | Q15: =IF(J15=0,0,K15+IF(M15<=O15,'تنظیمات'!$B$7,0)+IF(M15=1,P15,0)) | R15: ='سطرهای تسهیم'!F6 | S15: ='سطرهای تسهیم'!G6 | T15: =IFERROR(INDEX('دسته‌ها'!$D$5:$D$25,MATCH(S15,'دسته‌ها'!$A$5:$A$25,0)),"خیر")
A16: ='سطرهای تسهیم'!A6 | B16: ='سطرهای تسهیم'!B6 | C16: ='واحدها'!A7 | D16: ='واحدها'!H7 | E16: ='سطرهای تسهیم'!D6 | F16: ='سطرهای تسهیم'!E6 | G16: =IF('واحدها'!F7="بله",'شمول'!D5,0) | H16: =CHOOSE(MATCH(E16,'فهرست‌ها'!$A$4:$A$13,0),1,'واحدها'!E7,'واحدها'!D7*100,'واحدها'!J7,'واحدها'!J7,'وزن‌ها'!D5,'وزن‌ها'!D5,'واحدها'!K7,'واحدها'!L7,0) | I16: =G16*H16 | J16: =SUMIFS($I$5:$I$265,$A$5:$A$265,A16) | K16: =IF(J16=0,0,'تنظیمات'!$B$7*INT(F16*I16/(J16*'تنظیمات'!$B$7))) | L16: =IF(J16=0,0,F16*I16-J16*'تنظیمات'!$B$7*INT(F16*I16/(J16*'تنظیمات'!$B$7))) | M16: =1+COUNTIFS($A$5:$A$265,A16,$L$5:$L$265,">"&L16)+COUNTIFS($A$5:$A$265,A16,$L$5:$L$265,L16,$D$5:$D$265,"<"&D16) | N16: =IF(J16=0,0,F16-SUMIFS($K$5:$K$265,$A$5:$A$265,A16)) | O16: =INT(N16/'تنظیمات'!$B$7) | P16: =N16-O16*'تنظیمات'!$B$7 | Q16: =IF(J16=0,0,K16+IF(M16<=O16,'تنظیمات'!$B$7,0)+IF(M16=1,P16,0)) | R16: ='سطرهای تسهیم'!F6 | S16: ='سطرهای تسهیم'!G6 | T16: =IFERROR(INDEX('دسته‌ها'!$D$5:$D$25,MATCH(S16,'دسته‌ها'!$A$5:$A$25,0)),"خیر")
A17: ='سطرهای تسهیم'!A6 | B17: ='سطرهای تسهیم'!B6 | C17: ='واحدها'!A8 | D17: ='واحدها'!H8 | E17: ='سطرهای تسهیم'!D6 | F17: ='سطرهای تسهیم'!E6 | G17: =IF('واحدها'!F8="بله",'شمول'!E5,0) | H17: =CHOOSE(MATCH(E17,'فهرست‌ها'!$A$4:$A$13,0),1,'واحدها'!E8,'واحدها'!D8*100,'واحدها'!J8,'واحدها'!J8,'وزن‌ها'!E5,'وزن‌ها'!E5,'واحدها'!K8,'واحدها'!L8,0) | I17: =G17*H17 | J17: =SUMIFS($I$5:$I$265,$A$5:$A$265,A17) | K17: =IF(J17=0,0,'تنظیمات'!$B$7*INT(F17*I17/(J17*'تنظیمات'!$B$7))) | L17: =IF(J17=0,0,F17*I17-J17*'تنظیمات'!$B$7*INT(F17*I17/(J17*'تنظیمات'!$B$7))) | M17: =1+COUNTIFS($A$5:$A$265,A17,$L$5:$L$265,">"&L17)+COUNTIFS($A$5:$A$265,A17,$L$5:$L$265,L17,$D$5:$D$265,"<"&D17) | N17: =IF(J17=0,0,F17-SUMIFS($K$5:$K$265,$A$5:$A$265,A17)) | O17: =INT(N17/'تنظیمات'!$B$7) | P17: =N17-O17*'تنظیمات'!$B$7 | Q17: =IF(J17=0,0,K17+IF(M17<=O17,'تنظیمات'!$B$7,0)+IF(M17=1,P17,0)) | R17: ='سطرهای تسهیم'!F6 | S17: ='سطرهای تسهیم'!G6 | T17: =IFERROR(INDEX('دسته‌ها'!$D$5:$D$25,MATCH(S17,'دسته‌ها'!$A$5:$A$25,0)),"خیر")
A18: ='سطرهای تسهیم'!A6 | B18: ='سطرهای تسهیم'!B6 | C18: ='واحدها'!A9 | D18: ='واحدها'!H9 | E18: ='سطرهای تسهیم'!D6 | F18: ='سطرهای تسهیم'!E6 | G18: =IF('واحدها'!F9="بله",'شمول'!F5,0) | H18: =CHOOSE(MATCH(E18,'فهرست‌ها'!$A$4:$A$13,0),1,'واحدها'!E9,'واحدها'!D9*100,'واحدها'!J9,'واحدها'!J9,'وزن‌ها'!F5,'وزن‌ها'!F5,'واحدها'!K9,'واحدها'!L9,0) | I18: =G18*H18 | J18: =SUMIFS($I$5:$I$265,$A$5:$A$265,A18) | K18: =IF(J18=0,0,'تنظیمات'!$B$7*INT(F18*I18/(J18*'تنظیمات'!$B$7))) | L18: =IF(J18=0,0,F18*I18-J18*'تنظیمات'!$B$7*INT(F18*I18/(J18*'تنظیمات'!$B$7))) | M18: =1+COUNTIFS($A$5:$A$265,A18,$L$5:$L$265,">"&L18)+COUNTIFS($A$5:$A$265,A18,$L$5:$L$265,L18,$D$5:$D$265,"<"&D18) | N18: =IF(J18=0,0,F18-SUMIFS($K$5:$K$265,$A$5:$A$265,A18)) | O18: =INT(N18/'تنظیمات'!$B$7) | P18: =N18-O18*'تنظیمات'!$B$7 | Q18: =IF(J18=0,0,K18+IF(M18<=O18,'تنظیمات'!$B$7,0)+IF(M18=1,P18,0)) | R18: ='سطرهای تسهیم'!F6 | S18: ='سطرهای تسهیم'!G6 | T18: =IFERROR(INDEX('دسته‌ها'!$D$5:$D$25,MATCH(S18,'دسته‌ها'!$A$5:$A$25,0)),"خیر")
A19: ='سطرهای تسهیم'!A6 | B19: ='سطرهای تسهیم'!B6 | C19: ='واحدها'!A10 | D19: ='واحدها'!H10 | E19: ='سطرهای تسهیم'!D6 | F19: ='سطرهای تسهیم'!E6 | G19: =IF('واحدها'!F10="بله",'شمول'!G5,0) | H19: =CHOOSE(MATCH(E19,'فهرست‌ها'!$A$4:$A$13,0),1,'واحدها'!E10,'واحدها'!D10*100,'واحدها'!J10,'واحدها'!J10,'وزن‌ها'!G5,'وزن‌ها'!G5,'واحدها'!K10,'واحدها'!L10,0) | I19: =G19*H19 | J19: =SUMIFS($I$5:$I$265,$A$5:$A$265,A19) | K19: =IF(J19=0,0,'تنظیمات'!$B$7*INT(F19*I19/(J19*'تنظیمات'!$B$7))) | L19: =IF(J19=0,0,F19*I19-J19*'تنظیمات'!$B$7*INT(F19*I19/(J19*'تنظیمات'!$B$7))) | M19: =1+COUNTIFS($A$5:$A$265,A19,$L$5:$L$265,">"&L19)+COUNTIFS($A$5:$A$265,A19,$L$5:$L$265,L19,$D$5:$D$265,"<"&D19) | N19: =IF(J19=0,0,F19-SUMIFS($K$5:$K$265,$A$5:$A$265,A19)) | O19: =INT(N19/'تنظیمات'!$B$7) | P19: =N19-O19*'تنظیمات'!$B$7 | Q19: =IF(J19=0,0,K19+IF(M19<=O19,'تنظیمات'!$B$7,0)+IF(M19=1,P19,0)) | R19: ='سطرهای تسهیم'!F6 | S19: ='سطرهای تسهیم'!G6 | T19: =IFERROR(INDEX('دسته‌ها'!$D$5:$D$25,MATCH(S19,'دسته‌ها'!$A$5:$A$25,0)),"خیر")
A20: ='سطرهای تسهیم'!A6 | B20: ='سطرهای تسهیم'!B6 | C20: ='واحدها'!A11 | D20: ='واحدها'!H11 | E20: ='سطرهای تسهیم'!D6 | F20: ='سطرهای تسهیم'!E6 | G20: =IF('واحدها'!F11="بله",'شمول'!H5,0) | H20: =CHOOSE(MATCH(E20,'فهرست‌ها'!$A$4:$A$13,0),1,'واحدها'!E11,'واحدها'!D11*100,'واحدها'!J11,'واحدها'!J11,'وزن‌ها'!H5,'وزن‌ها'!H5,'واحدها'!K11,'واحدها'!L11,0) | I20: =G20*H20 | J20: =SUMIFS($I$5:$I$265,$A$5:$A$265,A20) | K20: =IF(J20=0,0,'تنظیمات'!$B$7*INT(F20*I20/(J20*'تنظیمات'!$B$7))) | L20: =IF(J20=0,0,F20*I20-J20*'تنظیمات'!$B$7*INT(F20*I20/(J20*'تنظیمات'!$B$7))) | M20: =1+COUNTIFS($A$5:$A$265,A20,$L$5:$L$265,">"&L20)+COUNTIFS($A$5:$A$265,A20,$L$5:$L$265,L20,$D$5:$D$265,"<"&D20) | N20: =IF(J20=0,0,F20-SUMIFS($K$5:$K$265,$A$5:$A$265,A20)) | O20: =INT(N20/'تنظیمات'!$B$7) | P20: =N20-O20*'تنظیمات'!$B$7 | Q20: =IF(J20=0,0,K20+IF(M20<=O20,'تنظیمات'!$B$7,0)+IF(M20=1,P20,0)) | R20: ='سطرهای تسهیم'!F6 | S20: ='سطرهای تسهیم'!G6 | T20: =IFERROR(INDEX('دسته‌ها'!$D$5:$D$25,MATCH(S20,'دسته‌ها'!$A$5:$A$25,0)),"خیر")
A21: ='سطرهای تسهیم'!A6 | B21: ='سطرهای تسهیم'!B6 | C21: ='واحدها'!A12 | D21: ='واحدها'!H12 | E21: ='سطرهای تسهیم'!D6 | F21: ='سطرهای تسهیم'!E6 | G21: =IF('واحدها'!F12="بله",'شمول'!I5,0) | H21: =CHOOSE(MATCH(E21,'فهرست‌ها'!$A$4:$A$13,0),1,'واحدها'!E12,'واحدها'!D12*100,'واحدها'!J12,'واحدها'!J12,'وزن‌ها'!I5,'وزن‌ها'!I5,'واحدها'!K12,'واحدها'!L12,0) | I21: =G21*H21 | J21: =SUMIFS($I$5:$I$265,$A$5:$A$265,A21) | K21: =IF(J21=0,0,'تنظیمات'!$B$7*INT(F21*I21/(J21*'تنظیمات'!$B$7))) | L21: =IF(J21=0,0,F21*I21-J21*'تنظیمات'!$B$7*INT(F21*I21/(J21*'تنظیمات'!$B$7))) | M21: =1+COUNTIFS($A$5:$A$265,A21,$L$5:$L$265,">"&L21)+COUNTIFS($A$5:$A$265,A21,$L$5:$L$265,L21,$D$5:$D$265,"<"&D21) | N21: =IF(J21=0,0,F21-SUMIFS($K$5:$K$265,$A$5:$A$265,A21)) | O21: =INT(N21/'تنظیمات'!$B$7) | P21: =N21-O21*'تنظیمات'!$B$7 | Q21: =IF(J21=0,0,K21+IF(M21<=O21,'تنظیمات'!$B$7,0)+IF(M21=1,P21,0)) | R21: ='سطرهای تسهیم'!F6 | S21: ='سطرهای تسهیم'!G6 | T21: =IFERROR(INDEX('دسته‌ها'!$D$5:$D$25,MATCH(S21,'دسته‌ها'!$A$5:$A$25,0)),"خیر")
A22: ='سطرهای تسهیم'!A6 | B22: ='سطرهای تسهیم'!B6 | C22: ='واحدها'!A13 | D22: ='واحدها'!H13 | E22: ='سطرهای تسهیم'!D6 | F22: ='سطرهای تسهیم'!E6 | G22: =IF('واحدها'!F13="بله",'شمول'!J5,0) | H22: =CHOOSE(MATCH(E22,'فهرست‌ها'!$A$4:$A$13,0),1,'واحدها'!E13,'واحدها'!D13*100,'واحدها'!J13,'واحدها'!J13,'وزن‌ها'!J5,'وزن‌ها'!J5,'واحدها'!K13,'واحدها'!L13,0) | I22: =G22*H22 | J22: =SUMIFS($I$5:$I$265,$A$5:$A$265,A22) | K22: =IF(J22=0,0,'تنظیمات'!$B$7*INT(F22*I22/(J22*'تنظیمات'!$B$7))) | L22: =IF(J22=0,0,F22*I22-J22*'تنظیمات'!$B$7*INT(F22*I22/(J22*'تنظیمات'!$B$7))) | M22: =1+COUNTIFS($A$5:$A$265,A22,$L$5:$L$265,">"&L22)+COUNTIFS($A$5:$A$265,A22,$L$5:$L$265,L22,$D$5:$D$265,"<"&D22) | N22: =IF(J22=0,0,F22-SUMIFS($K$5:$K$265,$A$5:$A$265,A22)) | O22: =INT(N22/'تنظیمات'!$B$7) | P22: =N22-O22*'تنظیمات'!$B$7 | Q22: =IF(J22=0,0,K22+IF(M22<=O22,'تنظیمات'!$B$7,0)+IF(M22=1,P22,0)) | R22: ='سطرهای تسهیم'!F6 | S22: ='سطرهای تسهیم'!G6 | T22: =IFERROR(INDEX('دسته‌ها'!$D$5:$D$25,MATCH(S22,'دسته‌ها'!$A$5:$A$25,0)),"خیر")
A23: ='سطرهای تسهیم'!A7 | B23: ='سطرهای تسهیم'!B7 | C23: ='واحدها'!A5 | D23: ='واحدها'!H5 | E23: ='سطرهای تسهیم'!D7 | F23: ='سطرهای تسهیم'!E7 | G23: =IF('واحدها'!F5="بله",'شمول'!B6,0) | H23: =CHOOSE(MATCH(E23,'فهرست‌ها'!$A$4:$A$13,0),1,'واحدها'!E5,'واحدها'!D5*100,'واحدها'!J5,'واحدها'!J5,'وزن‌ها'!B6,'وزن‌ها'!B6,'واحدها'!K5,'واحدها'!L5,0) | I23: =G23*H23 | J23: =SUMIFS($I$5:$I$265,$A$5:$A$265,A23) | K23: =IF(J23=0,0,'تنظیمات'!$B$7*INT(F23*I23/(J23*'تنظیمات'!$B$7))) | L23: =IF(J23=0,0,F23*I23-J23*'تنظیمات'!$B$7*INT(F23*I23/(J23*'تنظیمات'!$B$7))) | M23: =1+COUNTIFS($A$5:$A$265,A23,$L$5:$L$265,">"&L23)+COUNTIFS($A$5:$A$265,A23,$L$5:$L$265,L23,$D$5:$D$265,"<"&D23) | N23: =IF(J23=0,0,F23-SUMIFS($K$5:$K$265,$A$5:$A$265,A23)) | O23: =INT(N23/'تنظیمات'!$B$7) | P23: =N23-O23*'تنظیمات'!$B$7 | Q23: =IF(J23=0,0,K23+IF(M23<=O23,'تنظیمات'!$B$7,0)+IF(M23=1,P23,0)) | R23: ='سطرهای تسهیم'!F7 | S23: ='سطرهای تسهیم'!G7 | T23: =IFERROR(INDEX('دسته‌ها'!$D$5:$D$25,MATCH(S23,'دسته‌ها'!$A$5:$A$25,0)),"خیر")
A24: ='سطرهای تسهیم'!A7 | B24: ='سطرهای تسهیم'!B7 | C24: ='واحدها'!A6 | D24: ='واحدها'!H6 | E24: ='سطرهای تسهیم'!D7 | F24: ='سطرهای تسهیم'!E7 | G24: =IF('واحدها'!F6="بله",'شمول'!C6,0) | H24: =CHOOSE(MATCH(E24,'فهرست‌ها'!$A$4:$A$13,0),1,'واحدها'!E6,'واحدها'!D6*100,'واحدها'!J6,'واحدها'!J6,'وزن‌ها'!C6,'وزن‌ها'!C6,'واحدها'!K6,'واحدها'!L6,0) | I24: =G24*H24 | J24: =SUMIFS($I$5:$I$265,$A$5:$A$265,A24) | K24: =IF(J24=0,0,'تنظیمات'!$B$7*INT(F24*I24/(J24*'تنظیمات'!$B$7))) | L24: =IF(J24=0,0,F24*I24-J24*'تنظیمات'!$B$7*INT(F24*I24/(J24*'تنظیمات'!$B$7))) | M24: =1+COUNTIFS($A$5:$A$265,A24,$L$5:$L$265,">"&L24)+COUNTIFS($A$5:$A$265,A24,$L$5:$L$265,L24,$D$5:$D$265,"<"&D24) | N24: =IF(J24=0,0,F24-SUMIFS($K$5:$K$265,$A$5:$A$265,A24)) | O24: =INT(N24/'تنظیمات'!$B$7) | P24: =N24-O24*'تنظیمات'!$B$7 | Q24: =IF(J24=0,0,K24+IF(M24<=O24,'تنظیمات'!$B$7,0)+IF(M24=1,P24,0)) | R24: ='سطرهای تسهیم'!F7 | S24: ='سطرهای تسهیم'!G7 | T24: =IFERROR(INDEX('دسته‌ها'!$D$5:$D$25,MATCH(S24,'دسته‌ها'!$A$5:$A$25,0)),"خیر")
A25: ='سطرهای تسهیم'!A7 | B25: ='سطرهای تسهیم'!B7 | C25: ='واحدها'!A7 | D25: ='واحدها'!H7 | E25: ='سطرهای تسهیم'!D7 | F25: ='سطرهای تسهیم'!E7 | G25: =IF('واحدها'!F7="بله",'شمول'!D6,0) | H25: =CHOOSE(MATCH(E25,'فهرست‌ها'!$A$4:$A$13,0),1,'واحدها'!E7,'واحدها'!D7*100,'واحدها'!J7,'واحدها'!J7,'وزن‌ها'!D6,'وزن‌ها'!D6,'واحدها'!K7,'واحدها'!L7,0) | I25: =G25*H25 | J25: =SUMIFS($I$5:$I$265,$A$5:$A$265,A25) | K25: =IF(J25=0,0,'تنظیمات'!$B$7*INT(F25*I25/(J25*'تنظیمات'!$B$7))) | L25: =IF(J25=0,0,F25*I25-J25*'تنظیمات'!$B$7*INT(F25*I25/(J25*'تنظیمات'!$B$7))) | M25: =1+COUNTIFS($A$5:$A$265,A25,$L$5:$L$265,">"&L25)+COUNTIFS($A$5:$A$265,A25,$L$5:$L$265,L25,$D$5:$D$265,"<"&D25) | N25: =IF(J25=0,0,F25-SUMIFS($K$5:$K$265,$A$5:$A$265,A25)) | O25: =INT(N25/'تنظیمات'!$B$7) | P25: =N25-O25*'تنظیمات'!$B$7 | Q25: =IF(J25=0,0,K25+IF(M25<=O25,'تنظیمات'!$B$7,0)+IF(M25=1,P25,0)) | R25: ='سطرهای تسهیم'!F7 | S25: ='سطرهای تسهیم'!G7 | T25: =IFERROR(INDEX('دسته‌ها'!$D$5:$D$25,MATCH(S25,'دسته‌ها'!$A$5:$A$25,0)),"خیر")
A26: ='سطرهای تسهیم'!A7 | B26: ='سطرهای تسهیم'!B7 | C26: ='واحدها'!A8 | D26: ='واحدها'!H8 | E26: ='سطرهای تسهیم'!D7 | F26: ='سطرهای تسهیم'!E7 | G26: =IF('واحدها'!F8="بله",'شمول'!E6,0) | H26: =CHOOSE(MATCH(E26,'فهرست‌ها'!$A$4:$A$13,0),1,'واحدها'!E8,'واحدها'!D8*100,'واحدها'!J8,'واحدها'!J8,'وزن‌ها'!E6,'وزن‌ها'!E6,'واحدها'!K8,'واحدها'!L8,0) | I26: =G26*H26 | J26: =SUMIFS($I$5:$I$265,$A$5:$A$265,A26) | K26: =IF(J26=0,0,'تنظیمات'!$B$7*INT(F26*I26/(J26*'تنظیمات'!$B$7))) | L26: =IF(J26=0,0,F26*I26-J26*'تنظیمات'!$B$7*INT(F26*I26/(J26*'تنظیمات'!$B$7))) | M26: =1+COUNTIFS($A$5:$A$265,A26,$L$5:$L$265,">"&L26)+COUNTIFS($A$5:$A$265,A26,$L$5:$L$265,L26,$D$5:$D$265,"<"&D26) | N26: =IF(J26=0,0,F26-SUMIFS($K$5:$K$265,$A$5:$A$265,A26)) | O26: =INT(N26/'تنظیمات'!$B$7) | P26: =N26-O26*'تنظیمات'!$B$7 | Q26: =IF(J26=0,0,K26+IF(M26<=O26,'تنظیمات'!$B$7,0)+IF(M26=1,P26,0)) | R26: ='سطرهای تسهیم'!F7 | S26: ='سطرهای تسهیم'!G7 | T26: =IFERROR(INDEX('دسته‌ها'!$D$5:$D$25,MATCH(S26,'دسته‌ها'!$A$5:$A$25,0)),"خیر")
A27: ='سطرهای تسهیم'!A7 | B27: ='سطرهای تسهیم'!B7 | C27: ='واحدها'!A9 | D27: ='واحدها'!H9 | E27: ='سطرهای تسهیم'!D7 | F27: ='سطرهای تسهیم'!E7 | G27: =IF('واحدها'!F9="بله",'شمول'!F6,0) | H27: =CHOOSE(MATCH(E27,'فهرست‌ها'!$A$4:$A$13,0),1,'واحدها'!E9,'واحدها'!D9*100,'واحدها'!J9,'واحدها'!J9,'وزن‌ها'!F6,'وزن‌ها'!F6,'واحدها'!K9,'واحدها'!L9,0) | I27: =G27*H27 | J27: =SUMIFS($I$5:$I$265,$A$5:$A$265,A27) | K27: =IF(J27=0,0,'تنظیمات'!$B$7*INT(F27*I27/(J27*'تنظیمات'!$B$7))) | L27: =IF(J27=0,0,F27*I27-J27*'تنظیمات'!$B$7*INT(F27*I27/(J27*'تنظیمات'!$B$7))) | M27: =1+COUNTIFS($A$5:$A$265,A27,$L$5:$L$265,">"&L27)+COUNTIFS($A$5:$A$265,A27,$L$5:$L$265,L27,$D$5:$D$265,"<"&D27) | N27: =IF(J27=0,0,F27-SUMIFS($K$5:$K$265,$A$5:$A$265,A27)) | O27: =INT(N27/'تنظیمات'!$B$7) | P27: =N27-O27*'تنظیمات'!$B$7 | Q27: =IF(J27=0,0,K27+IF(M27<=O27,'تنظیمات'!$B$7,0)+IF(M27=1,P27,0)) | R27: ='سطرهای تسهیم'!F7 | S27: ='سطرهای تسهیم'!G7 | T27: =IFERROR(INDEX('دسته‌ها'!$D$5:$D$25,MATCH(S27,'دسته‌ها'!$A$5:$A$25,0)),"خیر")
A28: ='سطرهای تسهیم'!A7 | B28: ='سطرهای تسهیم'!B7 | C28: ='واحدها'!A10 | D28: ='واحدها'!H10 | E28: ='سطرهای تسهیم'!D7 | F28: ='سطرهای تسهیم'!E7 | G28: =IF('واحدها'!F10="بله",'شمول'!G6,0) | H28: =CHOOSE(MATCH(E28,'فهرست‌ها'!$A$4:$A$13,0),1,'واحدها'!E10,'واحدها'!D10*100,'واحدها'!J10,'واحدها'!J10,'وزن‌ها'!G6,'وزن‌ها'!G6,'واحدها'!K10,'واحدها'!L10,0) | I28: =G28*H28 | J28: =SUMIFS($I$5:$I$265,$A$5:$A$265,A28) | K28: =IF(J28=0,0,'تنظیمات'!$B$7*INT(F28*I28/(J28*'تنظیمات'!$B$7))) | L28: =IF(J28=0,0,F28*I28-J28*'تنظیمات'!$B$7*INT(F28*I28/(J28*'تنظیمات'!$B$7))) | M28: =1+COUNTIFS($A$5:$A$265,A28,$L$5:$L$265,">"&L28)+COUNTIFS($A$5:$A$265,A28,$L$5:$L$265,L28,$D$5:$D$265,"<"&D28) | N28: =IF(J28=0,0,F28-SUMIFS($K$5:$K$265,$A$5:$A$265,A28)) | O28: =INT(N28/'تنظیمات'!$B$7) | P28: =N28-O28*'تنظیمات'!$B$7 | Q28: =IF(J28=0,0,K28+IF(M28<=O28,'تنظیمات'!$B$7,0)+IF(M28=1,P28,0)) | R28: ='سطرهای تسهیم'!F7 | S28: ='سطرهای تسهیم'!G7 | T28: =IFERROR(INDEX('دسته‌ها'!$D$5:$D$25,MATCH(S28,'دسته‌ها'!$A$5:$A$25,0)),"خیر")
A29: ='سطرهای تسهیم'!A7 | B29: ='سطرهای تسهیم'!B7 | C29: ='واحدها'!A11 | D29: ='واحدها'!H11 | E29: ='سطرهای تسهیم'!D7 | F29: ='سطرهای تسهیم'!E7 | G29: =IF('واحدها'!F11="بله",'شمول'!H6,0) | H29: =CHOOSE(MATCH(E29,'فهرست‌ها'!$A$4:$A$13,0),1,'واحدها'!E11,'واحدها'!D11*100,'واحدها'!J11,'واحدها'!J11,'وزن‌ها'!H6,'وزن‌ها'!H6,'واحدها'!K11,'واحدها'!L11,0) | I29: =G29*H29 | J29: =SUMIFS($I$5:$I$265,$A$5:$A$265,A29) | K29: =IF(J29=0,0,'تنظیمات'!$B$7*INT(F29*I29/(J29*'تنظیمات'!$B$7))) | L29: =IF(J29=0,0,F29*I29-J29*'تنظیمات'!$B$7*INT(F29*I29/(J29*'تنظیمات'!$B$7))) | M29: =1+COUNTIFS($A$5:$A$265,A29,$L$5:$L$265,">"&L29)+COUNTIFS($A$5:$A$265,A29,$L$5:$L$265,L29,$D$5:$D$265,"<"&D29) | N29: =IF(J29=0,0,F29-SUMIFS($K$5:$K$265,$A$5:$A$265,A29)) | O29: =INT(N29/'تنظیمات'!$B$7) | P29: =N29-O29*'تنظیمات'!$B$7 | Q29: =IF(J29=0,0,K29+IF(M29<=O29,'تنظیمات'!$B$7,0)+IF(M29=1,P29,0)) | R29: ='سطرهای تسهیم'!F7 | S29: ='سطرهای تسهیم'!G7 | T29: =IFERROR(INDEX('دسته‌ها'!$D$5:$D$25,MATCH(S29,'دسته‌ها'!$A$5:$A$25,0)),"خیر")
A30: ='سطرهای تسهیم'!A7 | B30: ='سطرهای تسهیم'!B7 | C30: ='واحدها'!A12 | D30: ='واحدها'!H12 | E30: ='سطرهای تسهیم'!D7 | F30: ='سطرهای تسهیم'!E7 | G30: =IF('واحدها'!F12="بله",'شمول'!I6,0) | H30: =CHOOSE(MATCH(E30,'فهرست‌ها'!$A$4:$A$13,0),1,'واحدها'!E12,'واحدها'!D12*100,'واحدها'!J12,'واحدها'!J12,'وزن‌ها'!I6,'وزن‌ها'!I6,'واحدها'!K12,'واحدها'!L12,0) | I30: =G30*H30 | J30: =SUMIFS($I$5:$I$265,$A$5:$A$265,A30) | K30: =IF(J30=0,0,'تنظیمات'!$B$7*INT(F30*I30/(J30*'تنظیمات'!$B$7))) | L30: =IF(J30=0,0,F30*I30-J30*'تنظیمات'!$B$7*INT(F30*I30/(J30*'تنظیمات'!$B$7))) | M30: =1+COUNTIFS($A$5:$A$265,A30,$L$5:$L$265,">"&L30)+COUNTIFS($A$5:$A$265,A30,$L$5:$L$265,L30,$D$5:$D$265,"<"&D30) | N30: =IF(J30=0,0,F30-SUMIFS($K$5:$K$265,$A$5:$A$265,A30)) | O30: =INT(N30/'تنظیمات'!$B$7) | P30: =N30-O30*'تنظیمات'!$B$7 | Q30: =IF(J30=0,0,K30+IF(M30<=O30,'تنظیمات'!$B$7,0)+IF(M30=1,P30,0)) | R30: ='سطرهای تسهیم'!F7 | S30: ='سطرهای تسهیم'!G7 | T30: =IFERROR(INDEX('دسته‌ها'!$D$5:$D$25,MATCH(S30,'دسته‌ها'!$A$5:$A$25,0)),"خیر")
